Workbook

Sheet TABLA
A3: Suma de DÓLARES | B3: Etiquetas de columna
A4: Etiquetas de fila | B4: 1 | C4: 2 | D4: 3 | E4: 4 | F4: 5 | G4: 6 | H4: 7 | I4: 8 | J4: 9 | K4: 10 | L4: 11 | M4: 12 | N4: Total general
A5: ROGELIO CURIEL | B5: 810952.75 | C5: 1184653.2 | D5: 994455.1 | E5: 724805.8 | F5: 1633465 | G5: 729224.49 | H5: 652691.6 | I5: 1683256.9 | J5: 321523.75 | K5: 1088738 | L5: 1635138.8 | M5: 247884.6 | N5: 11706790 | O5: =+GETPIVOTDATA("DÓLARES",$A$3,"VENDEDOR","ROGELIO CURIEL") -> 11706790
A6: RADAMES BAEZ | B6: 27547 | C6: 40477.8 | D6: 29907 | E6: 74949.4 | F6: 151776 | G6: 174464.3 | H6: 190704 | I6: 200676.9 | J6: 209127.8 | K6: 188806 | L6: 101914.4 | M6: 62108 | N6: 1452458.6 | O6: 600000
A7: RODOLFO AYALA | B7: 64129.4 | C7: 72765.4 | D7: 149192.89 | E7: 47151.08 | F7: 29428.28 | G7: 230317.84 | H7: 72517.46 | I7: 121061.37 | J7: 211717.37 | K7: 132778.32 | L7: 143867.95 | M7: 126823.4 | N7: 1401750.8 | O7: 1300000
A8: EDGAR MUÑOZ | B8: 23580.4 | C8: 31668.9 | D8: 57246.2 | E8: 76793.4 | F8: 106991.2 | G8: 144730 | H8: 162258.7 | I8: 129524.4 | J8: 119286.2 | K8: 144718.65 | L8: 169560.4 | M8: 141183.45 | N8: 1307541.9 | O8: 600000
A9: RICARDO RODRIGUEZ | B9: 60764.229 | C9: 55066.59 | D9: 52036.823 | E9: 66796.632 | F9: 52167.815 | G9: 55772.181 | H9: 69239.782 | I9: 55056.156 | J9: 67943.199 | K9: 60817.601 | L9: 68203.518 | M9: 57161.015 | N9: 721025.54 | O9: =+GETPIVOTDATA("DÓLARES",$A$3,"VENDEDOR","RICARDO RODRIGUEZ") -> 721025.54
A10: EDUARDO PERALTA | F10: 1750 | H10: 12606 | K10: 91060 | N10: 105416 | O10: =+GETPIVOTDATA("DÓLARES",$A$3,"VENDEDOR","EDUARDO PERALTA") -> 105416
A11: Total general | B11: 986973.78 | C11: 1384631.9 | D11: 1282838 | E11: 990496.31 | F11: 1975578.3 | G11: 1334508.8 | H11: 1160017.5 | I11: 2189575.7 | J11: 929598.32 | K11: 1706918.6 | L11: 2118685.1 | M11: 635160.47 | N11: 16694983 | O11: =SUM(O5:O10) -> 15033232 | P11: =+O11*18 -> 2.7059817e+08
B12: 986973.78 | C12: 1384631.9 | D12: 1282838 | E12: 990496.31 | F12: 1975578.3 | G12: 1334508.8 | H12: 1160017.5 | I12: 2189575.7 | J12: 929598.32 | K12: 1706918.6 | L12: 2118685.1 | M12: 635160.47
B13: 18 | C13: 18 | D13: 18 | E13: 18 | F13: 18 | G13: 18 | H13: 18 | I13: 18 | J13: 18 | K13: 18 | L13: 18 | M13: 18 | O13: =+O11-O9 -> 14312206
B15: =+B12*B13 -> 17765528 | C15: =+C12*C13 -> 24923374 | D15: =+D12*D13 -> 23091084 | E15: =+E12*E13 -> 17828934 | F15: =+F12*F13 -> 35560409 | G15: =+G12*G13 -> 24021159 | H15: =+H12*H13 -> 20880316 | I15: =+I12*I13 -> 39412363 | ... M15: =+M12*M13 -> 11432888 | N15: =SUM(B15:M15) -> 3.0050969e+08
N17: =+N19/N18 -> 18 | O17: 18
N18: =+GETPIVOTDATA("DÓLARES",$A$3) -> 16694983 | O18: =+O13*O17 -> 2.5761971e+08
N19: =+GETPIVOTDATA("DÓLARES",$A$3)*18 -> 3.0050969e+08 | O19: =+O11*18 -> 2.7059817e+08

Sheet BD
A2: CODIGO | B2: FILAS | C2: MESES | D2: CLAVE | F2: NOMBRE DEL CLIENTE | G2: CLAVE DEL PRODUCTO SKU | H2: PRODUCTO | I2: AREA | J2: VENDEDOR | K2: PRECIO UNITARIO EN DÓLARES | L2: TIPO | M2: VOLUMEN | N2: PU | O2: DÓLARES
A3: 1 | B3: 1 | C3: 1 | D3: 28 | E3: =VLOOKUP(D3,[1]Hoja1!$C$2:$D$49697,2,0) -> CERVECERIA CUAUHTEMOC MOCTEZUMA SA DE CV | F3: CERVECERIA CUAUHTEMOC MOCTEZUMA SA DE CV | G3: MP-0308 | H3: ULTRAFLO PRIME CONTENEDOR | I3: CERVEZA | J3: ROGELIO CURIEL | K3: 28.78 | L3: PRESUPUESTO | M3: {=INDEX(ACUMULADO!$J$5:$U$240,BD!B3,BD!C3)} -> 0 | N3: =IFERROR(O3/M3,0) -> 0 | O3: {=INDEX(ACUMULADO!$X$5:$AI$240,BD!B3,BD!C3)} -> 0
A4: 2 | B4: =IF(B3=236,1,B3+1) -> 2 | C4: =IF(B3=236,C3+1,C3) -> 1 | D4: 28 | E4: =VLOOKUP(D4,[1]Hoja1!$C$2:$D$49697,2,0) -> CERVECERIA CUAUHTEMOC MOCTEZUMA SA DE CV | F4: CERVECERIA CUAUHTEMOC MOCTEZUMA SA DE CV | G4: MP-0316 | H4: ATTENUZYME PRIME CONTENEDOR | I4: CERVEZA | J4: ROGELIO CURIEL | K4: 25.75 | L4: PRESUPUESTO | M4: {=INDEX(ACUMULADO!$J$5:$U$240,BD!B4,BD!C4)} -> 2200 | N4: =IFERROR(O4/M4,0) -> 25.75 | O4: {=INDEX(ACUMULADO!$X$5:$AI$240,BD!B4,BD!C4)} -> 56650
A5: 3 | B5: =IF(B4=236,1,B4+1) -> 3 | C5: =IF(B4=236,C4+1,C4) -> 1 | D5: 28 | E5: =VLOOKUP(D5,[1]Hoja1!$C$2:$D$49697,2,0) -> CERVECERIA CUAUHTEMOC MOCTEZUMA SA DE CV | F5: CERVECERIA CUAUHTEMOC MOCTEZUMA SA DE CV | G5: 169 | H5: CEREMIX PLUS MG | I5: CERVEZA | J5: ROGELIO CURIEL | K5: 16.9 | L5: PRESUPUESTO | M5: {=INDEX(ACUMULADO!$J$5:$U$240,BD!B5,BD!C5)} -> 0 | N5: =IFERROR(O5/M5,0) -> 0 | O5: {=INDEX(ACUMULADO!$X$5:$AI$240,BD!B5,BD!C5)} -> 0
A6: 4 | B6: =IF(B5=236,1,B5+1) -> 4 | C6: =IF(B5=236,C5+1,C5) -> 1 | D6: 28 | E6: =VLOOKUP(D6,[1]Hoja1!$C$2:$D$49697,2,0) -> CERVECERIA CUAUHTEMOC MOCTEZUMA SA DE CV | F6: CERVECERIA CUAUHTEMOC MOCTEZUMA SA DE CV | G6: CON-0246 | H6: TERMAMYL SC 4X CONTENEDOR 1200 KG | I6: CERVEZA | J6: ROGELIO CURIEL | K6: 12.73 | L6: PRESUPUESTO | M6: {=INDEX(ACUMULADO!$J$5:$U$240,BD!B6,BD!C6)} -> 0 | N6: =IFERROR(O6/M6,0) -> 0 | O6: {=INDEX(ACUMULADO!$X$5:$AI$240,BD!B6,BD!C6)} -> 0
A7: 5 | B7: =IF(B6=236,1,B6+1) -> 5 | C7: =IF(B6=236,C6+1,C6) -> 1 | D7: 28 | E7: =VLOOKUP(D7,[1]Hoja1!$C$2:$D$49697,2,0) -> CERVECERIA CUAUHTEMOC MOCTEZUMA SA DE CV | F7: CERVECERIA CUAUHTEMOC MOCTEZUMA SA DE CV | G7: MP-0184 | H7: MATUREX PRO | I7: CERVEZA | J7: ROGELIO CURIEL | K7: 81.36 | L7: PRESUPUESTO | M7: {=INDEX(ACUMULADO!$J$5:$U$240,BD!B7,BD!C7)} -> 180 | N7: =IFERROR(O7/M7,0) -> 81.36 | O7: {=INDEX(ACUMULADO!$X$5:$AI$240,BD!B7,BD!C7)} -> 14644.8
A8: 6 | B8: =IF(B7=236,1,B7+1) -> 6 | C8: =IF(B7=236,C7+1,C7) -> 1 | D8: 29 | E8: =VLOOKUP(D8,[1]Hoja1!$C$2:$D$49697,2,0) -> CERVECERIA CUAUHTEMOC MOCTEZUMA SA DE CV | F8: CERVECERIA CUAUHTEMOC MOCTEZUMA SA DE CV | G8: MP-0268 | H8: ULTRAFLO PRIME | I8: CERVEZA | J8: ROGELIO CURIEL | K8: 28.78 | L8: PRESUPUESTO | M8: {=INDEX(ACUMULADO!$J$5:$U$240,BD!B8,BD!C8)} -> 475 | N8: =IFERROR(O8/M8,0) -> 28.78 | O8: {=INDEX(ACUMULADO!$X$5:$AI$240,BD!B8,BD!C8)} -> 13670.5
A9: 7 | B9: =IF(B8=236,1,B8+1) -> 7 | C9: =IF(B8=236,C8+1,C8) -> 1 | D9: 29 | E9: =VLOOKUP(D9,[1]Hoja1!$C$2:$D$49697,2,0) -> CERVECERIA CUAUHTEMOC MOCTEZUMA SA DE CV | F9: CERVECERIA CUAUHTEMOC MOCTEZUMA SA DE CV | G9: MP-0317 | H9: ATTENUZYME PRIME | I9: CERVEZA | J9: ROGELIO CURIEL | K9: 25.75 | L9: PRESUPUESTO | M9: {=INDEX(ACUMULADO!$J$5:$U$240,BD!B9,BD!C9)} -> 1600 | N9: =IFERROR(O9/M9,0) -> 25.75 | O9: {=INDEX(ACUMULADO!$X$5:$AI$240,BD!B9,BD!C9)} -> 41200
A10: 8 | B10: =IF(B9=236,1,B9+1) -> 8 | C10: =IF(B9=236,C9+1,C9) -> 1 | D10: 29 | E10: =VLOOKUP(D10,[1]Hoja1!$C$2:$D$49697,2,0) -> CERVECERIA CUAUHTEMOC MOCTEZUMA SA DE CV | F10: CERVECERIA CUAUHTEMOC MOCTEZUMA SA DE CV | G10: 169 | H10: CEREMIX PLUS MG | I10: CERVEZA | J10: ROGELIO CURIEL | K10: 16.9 | L10: PRESUPUESTO | M10: {=INDEX(ACUMULADO!$J$5:$U$240,BD!B10,BD!C10)} -> 800 | N10: =IFERROR(O10/M10,0) -> 16.9 | O10: {=INDEX(ACUMULADO!$X$5:$AI$240,BD!B10,BD!C10)} -> 13520
A11: 9 | B11: =IF(B10=236,1,B10+1) -> 9 | C11: =IF(B10=236,C10+1,C10) -> 1 | D11: 29 | E11: =VLOOKUP(D11,[1]Hoja1!$C$2:$D$49697,2,0) -> CERVECERIA CUAUHTEMOC MOCTEZUMA SA DE CV | F11: CERVECERIA CUAUHTEMOC MOCTEZUMA SA DE CV | G11: MP-0184 | H11: MATUREX PRO | I11: CERVEZA | J11: ROGELIO CURIEL | K11: 81.36 | L11: PRESUPUESTO | M11: {=INDEX(ACUMULADO!$J$5:$U$240,BD!B11,BD!C11)} -> 60 | N11: =IFERROR(O11/M11,0) -> 81.36 | O11: {=INDEX(ACUMULADO!$X$5:$AI$240,BD!B11,BD!C11)} -> 4881.6
A12: 10 | B12: =IF(B11=236,1,B11+1) -> 10 | C12: =IF(B11=236,C11+1,C11) -> 1 | D12: 29 | E12: =VLOOKUP(D12,[1]Hoja1!$C$2:$D$49697,2,0) -> CERVECERIA CUAUHTEMOC MOCTEZUMA SA DE CV | F12: CERVECERIA CUAUHTEMOC MOCTEZUMA SA DE CV | G12: MP-0246 | H12: TERMAMYL SC 4X PORRON 25 KG | I12: CERVEZA | J12: ROGELIO CURIEL | K12: 12.73 | L12: PRESUPUESTO | M12: {=INDEX(ACUMULADO!$J$5:$U$240,BD!B12,BD!C12)} -> 300 | N12: =IFERROR(O12/M12,0) -> 12.73 | O12: {=INDEX(ACUMULADO!$X$5:$AI$240,BD!B12,BD!C12)} -> 3819
A13: 11 | B13: =IF(B12=236,1,B12+1) -> 11 | C13: =IF(B12=236,C12+1,C12) -> 1 | D13: 30 | E13: =VLOOKUP(D13,[1]Hoja1!$C$2:$D$49697,2,0) -> CERVECERIA CUAUHTEMOC MOCTEZUMA SA DE CV | F13: CERVECERIA CUAUHTEMOC MOCTEZUMA SA DE CV | G13: MP-0268 | H13: ULTRAFLO PRIME | I13: CERVEZA | J13: ROGELIO CURIEL | K13: 28.78 | L13: PRESUPUESTO | M13: {=INDEX(ACUMULADO!$J$5:$U$240,BD!B13,BD!C13)} -> 0 | N13: =IFERROR(O13/M13,0) -> 0 | O13: {=INDEX(ACUMULADO!$X$5:$AI$240,BD!B13,BD!C13)} -> 0
A14: 12 | B14: =IF(B13=236,1,B13+1) -> 12 | C14: =IF(B13=236,C13+1,C13) -> 1 | D14: 30 | E14: =VLOOKUP(D14,[1]Hoja1!$C$2:$D$49697,2,0) -> CERVECERIA CUAUHTEMOC MOCTEZUMA SA DE CV | F14: CERVECERIA CUAUHTEMOC MOCTEZUMA SA DE CV | G14: MP-0317 | H14: ATTENUZYME PRIME | I14: CERVEZA | J14: ROGELIO CURIEL | K14: 25.75 | L14: PRESUPUESTO | M14: {=INDEX(ACUMULADO!$J$5:$U$240,BD!B14,BD!C14)} -> 0 | N14: =IFERROR(O14/M14,0) -> 0 | O14: {=INDEX(ACUMULADO!$X$5:$AI$240,BD!B14,BD!C14)} -> 0
A15: 13 | B15: =IF(B14=236,1,B14+1) -> 13 | C15: =IF(B14=236,C14+1,C14) -> 1 | D15: 30 | E15: =VLOOKUP(D15,[1]Hoja1!$C$2:$D$49697,2,0) -> CERVECERIA CUAUHTEMOC MOCTEZUMA SA DE CV | F15: CERVECERIA CUAUHTEMOC MOCTEZUMA SA DE CV | G15: 169 | H15: CEREMIX PLUS MG | I15: CERVEZA | J15: ROGELIO CURIEL | K15: 16.9 | L15: PRESUPUESTO | M15: {=INDEX(ACUMULADO!$J$5:$U$240,BD!B15,BD!C15)} -> 0 | N15: =IFERROR(O15/M15,0) -> 0 | O15: {=INDEX(ACUMULADO!$X$5:$AI$240,BD!B15,BD!C15)} -> 0
A16: 14 | B16: =IF(B15=236,1,B15+1) -> 14 | C16: =IF(B15=236,C15+1,C15) -> 1 | D16: 30 | E16: =VLOOKUP(D16,[1]Hoja1!$C$2:$D$49697,2,0) -> CERVECERIA CUAUHTEMOC MOCTEZUMA SA DE CV | F16: CERVECERIA CUAUHTEMOC MOCTEZUMA SA DE CV | G16: MP-0246 | H16: TERMAMYL SC 4X PORRON 25 KG | I16: CERVEZA | J16: ROGELIO CURIEL | K16: 12.73 | L16: PRESUPUESTO | M16: {=INDEX(ACUMULADO!$J$5:$U$240,BD!B16,BD!C16)} -> 0 | N16: =IFERROR(O16/M16,0) -> 0 | O16: {=INDEX(ACUMULADO!$X$5:$AI$240,BD!B16,BD!C16)} -> 0
A17: 15 | B17: =IF(B16=236,1,B16+1) -> 15 | C17: =IF(B16=236,C16+1,C16) -> 1 | D17: 31 | E17: =VLOOKUP(D17,[1]Hoja1!$C$2:$D$49697,2,0) -> CERVECERIA CUAUHTEMOC MOCTEZUMA SA DE CV | F17: CERVECERIA CUAUHTEMOC MOCTEZUMA SA DE CV | G17: MP-0308 | H17: ULTRAFLO PRIME CONTENEDOR | I17: CERVEZA | J17: ROGELIO CURIEL | K17: 28.78 | L17: PRESUPUESTO | M17: {=INDEX(ACUMULADO!$J$5:$U$240,BD!B17,BD!C17)} -> 0 | N17: =IFERROR(O17/M17,0) -> 0 | O17: {=INDEX(ACUMULADO!$X$5:$AI$240,BD!B17,BD!C17)} -> 0
A18: 16 | B18: =IF(B17=236,1,B17+1) -> 16 | C18: =IF(B17=236,C17+1,C17) -> 1 | D18: 31 | E18: =VLOOKUP(D18,[1]Hoja1!$C$2:$D$49697,2,0) -> CERVECERIA CUAUHTEMOC MOCTEZUMA SA DE CV | F18: CERVECERIA CUAUHTEMOC MOCTEZUMA SA DE CV | G18: 169 | H18: CEREMIX PLUS MG | I18: CERVEZA | J18: ROGELIO CURIEL | K18: 16.9 | L18: PRESUPUESTO | M18: {=INDEX(ACUMULADO!$J$5:$U$240,BD!B18,BD!C18)} -> 0 | N18: =IFERROR(O18/M18,0) -> 0 | O18: {=INDEX(ACUMULADO!$X$5:$AI$240,BD!B18,BD!C18)} -> 0
A19: 17 | B19: =IF(B18=236,1,B18+1) -> 17 | C19: =IF(B18=236,C18+1,C18) -> 1 | D19: 31 | E19: =VLOOKUP(D19,[1]Hoja1!$C$2:$D$49697,2,0) -> CERVECERIA CUAUHTEMOC MOCTEZUMA SA DE CV | F19: CERVECERIA CUAUHTEMOC MOCTEZUMA SA DE CV | G19: MP-0184 | H19: MATUREX PRO | I19: CERVEZA | J19: ROGELIO CURIEL | K19: 81.36 | L19: PRESUPUESTO | M19: {=INDEX(ACUMULADO!$J$5:$U$240,BD!B19,BD!C19)} -> 0 | N19: =IFERROR(O19/M19,0) -> 0 | O19: {=INDEX(ACUMULADO!$X$5:$AI$240,BD!B19,BD!C19)} -> 0
A20: 18 | B20: =IF(B19=236,1,B19+1) -> 18 | C20: =IF(B19=236,C19+1,C19) -> 1 | D20: 31 | E20: =VLOOKUP(D20,[1]Hoja1!$C$2:$D$49697,2,0) -> CERVECERIA CUAUHTEMOC MOCTEZUMA SA DE CV | F20: CERVECERIA CUAUHTEMOC MOCTEZUMA SA DE CV | G20: CON-0246 | H20: TERMAMYL SC 4X CONTENEDOR 1200 KG | I20: CERVEZA | J20: ROGELIO CURIEL | K20: 12.73 | L20: PRESUPUESTO | M20: {=INDEX(ACUMULADO!$J$5:$U$240,BD!B20,BD!C20)} -> 0 | N20: =IFERROR(O20/M20,0) -> 0 | O20: {=INDEX(ACUMULADO!$X$5:$AI$240,BD!B20,BD!C20)} -> 0
A21: 19 | B21: =IF(B20=236,1,B20+1) -> 19 | C21: =IF(B20=236,C20+1,C20) -> 1 | D21: 32 | E21: =VLOOKUP(D21,[1]Hoja1!$C$2:$D$49697,2,0) -> CERVECERIA CUAUHTEMOC MOCTEZUMA SA DE CV | F21: CERVECERIA CUAUHTEMOC MOCTEZUMA SA DE CV | G21: MP-0044 | H21: ULTRAFLO MAX CONTENEDOR | I21: CERVEZA | J21: ROGELIO CURIEL | K21: 26.54 | L21: PRESUPUESTO | M21: {=INDEX(ACUMULADO!$J$5:$U$240,BD!B21,BD!C21)} -> 0 | N21: =IFERROR(O21/M21,0) -> 0 | O21: {=INDEX(ACUMULADO!$X$5:$AI$240,BD!B21,BD!C21)} -> 0
A22: 20 | B22: =IF(B21=236,1,B21+1) -> 20 | C22: =IF(B21=236,C21+1,C21) -> 1 | D22: 32 | E22: =VLOOKUP(D22,[1]Hoja1!$C$2:$D$49697,2,0) -> CERVECERIA CUAUHTEMOC MOCTEZUMA SA DE CV | F22: CERVECERIA CUAUHTEMOC MOCTEZUMA SA DE CV | G22: MP-0316 | H22: ATTENUZYME PRIME CONTENEDOR | I22: CERVEZA | J22: ROGELIO CURIEL | K22: 25.75 | L22: PRESUPUESTO | M22: {=INDEX(ACUMULADO!$J$5:$U$240,BD!B22,BD!C22)} -> 0 | N22: =IFERROR(O22/M22,0) -> 0 | O22: {=INDEX(ACUMULADO!$X$5:$AI$240,BD!B22,BD!C22)} -> 0
A23: 21 | B23: =IF(B22=236,1,B22+1) -> 21 | C23: =IF(B22=236,C22+1,C22) -> 1 | D23: 32 | E23: =VLOOKUP(D23,[1]Hoja1!$C$2:$D$49697,2,0) -> CERVECERIA CUAUHTEMOC MOCTEZUMA SA DE CV | F23: CERVECERIA CUAUHTEMOC MOCTEZUMA SA DE CV | G23: 169 | H23: CEREMIX PLUS MG | I23: CERVEZA | J23: ROGELIO CURIEL | K23: 16.9 | L23: PRESUPUESTO | M23: {=INDEX(ACUMULADO!$J$5:$U$240,BD!B23,BD!C23)} -> 0 | N23: =IFERROR(O23/M23,0) -> 0 | O23: {=INDEX(ACUMULADO!$X$5:$AI$240,BD!B23,BD!C23)} -> 0
A24: 22 | B24: =IF(B23=236,1,B23+1) -> 22 | C24: =IF(B23=236,C23+1,C23) -> 1 | D24: 32 | E24: =VLOOKUP(D24,[1]Hoja1!$C$2:$D$49697,2,0) -> CERVECERIA CUAUHTEMOC MOCTEZUMA SA DE CV | F24: CERVECERIA CUAUHTEMOC MOCTEZUMA SA DE CV | G24: MP-0184 | H24: MATUREX PRO | I24: CERVEZA | J24: ROGELIO CURIEL | K24: 81.36 | L24: PRESUPUESTO | M24: {=INDEX(ACUMULADO!$J$5:$U$240,BD!B24,BD!C24)} -> 0 | N24: =IFERROR(O24/M24,0) -> 0 | O24: {=INDEX(ACUMULADO!$X$5:$AI$240,BD!B24,BD!C24)} -> 0
A25: 23 | B25: =IF(B24=236,1,B24+1) -> 23 | C25: =IF(B24=236,C24+1,C24) -> 1 | D25: 32 | E25: =VLOOKUP(D25,[1]Hoja1!$C$2:$D$49697,2,0) -> CERVECERIA CUAUHTEMOC MOCTEZUMA SA DE CV | F25: CERVECERIA CUAUHTEMOC MOCTEZUMA SA DE CV | G25: CON-0343 | H25: TERMAMYL SC DS CONTENEDOR 1200 KG | I25: CERVEZA | J25: ROGELIO CURIEL | K25: 12.98 | L25: PRESUPUESTO | M25: {=INDEX(ACUMULADO!$J$5:$U$240,BD!B25,BD!C25)} -> 0 | N25: =IFERROR(O25/M25,0) -> 0 | O25: {=INDEX(ACUMULADO!$X$5:$AI$240,BD!B25,BD!C25)} -> 0
A26: 24 | B26: =IF(B25=236,1,B25+1) -> 24 | C26: =IF(B25=236,C25+1,C25) -> 1 | D26: 33 | E26: =VLOOKUP(D26,[1]Hoja1!$C$2:$D$49697,2,0) -> CERVECERIA CUAUHTEMOC MOCTEZUMA SA DE CV | F26: CERVECERIA CUAUHTEMOC MOCTEZUMA SA DE CV | G26: MP-0268 | H26: ULTRAFLO PRIME | I26: CERVEZA | J26: ROGELIO CURIEL | K26: 28.78 | L26: PRESUPUESTO | M26: {=INDEX(ACUMULADO!$J$5:$U$240,BD!B26,BD!C26)} -> 660 | N26: =IFERROR(O26/M26,0) -> 28.78 | O26: {=INDEX(ACUMULADO!$X$5:$AI$240,BD!B26,BD!C26)} -> 18994.8
A27: 25 | B27: =IF(B26=236,1,B26+1) -> 25 | C27: =IF(B26=236,C26+1,C26) -> 1 | D27: 33 | E27: =VLOOKUP(D27,[1]Hoja1!$C$2:$D$49697,2,0) -> CERVECERIA CUAUHTEMOC MOCTEZUMA SA DE CV | F27: CERVECERIA CUAUHTEMOC MOCTEZUMA SA DE CV | G27: MP-0317 | H27: ATTENUZYME PRIME | I27: CERVEZA | J27: ROGELIO CURIEL | K27: 25.75 | L27: PRESUPUESTO | M27: {=INDEX(ACUMULADO!$J$5:$U$240,BD!B27,BD!C27)} -> 2500 | N27: =IFERROR(O27/M27,0) -> 25.75 | O27: {=INDEX(ACUMULADO!$X$5:$AI$240,BD!B27,BD!C27)} -> 64375
A28: 26 | B28: =IF(B27=236,1,B27+1) -> 26 | C28: =IF(B27=236,C27+1,C27) -> 1 | D28: 33 | E28: =VLOOKUP(D28,[1]Hoja1!$C$2:$D$49697,2,0) -> CERVECERIA CUAUHTEMOC MOCTEZUMA SA DE CV | F28: CERVECERIA CUAUHTEMOC MOCTEZUMA SA DE CV | G28: 169 | H28: CEREMIX PLUS MG | I28: CERVEZA | J28: ROGELIO CURIEL | K28: 16.9 | L28: PRESUPUESTO | M28: {=INDEX(ACUMULADO!$J$5:$U$240,BD!B28,BD!C28)} -> 1000 | N28: =IFERROR(O28/M28,0) -> 16.9 | O28: {=INDEX(ACUMULADO!$X$5:$AI$240,BD!B28,BD!C28)} -> 16900
A29: 27 | B29: =IF(B28=236,1,B28+1) -> 27 | C29: =IF(B28=236,C28+1,C28) -> 1 | D29: 33 | E29: =VLOOKUP(D29,[1]Hoja1!$C$2:$D$49697,2,0) -> CERVECERIA CUAUHTEMOC MOCTEZUMA SA DE CV | F29: CERVECERIA CUAUHTEMOC MOCTEZUMA SA DE CV | G29: MP-0184 | H29: MATUREX PRO | I29: CERVEZA | J29: ROGELIO CURIEL | K29: 81.36 | L29: PRESUPUESTO | M29: {=INDEX(ACUMULADO!$J$5:$U$240,BD!B29,BD!C29)} -> 900 | N29: =IFERROR(O29/M29,0) -> 81.36 | O29: {=INDEX(ACUMULADO!$X$5:$AI$240,BD!B29,BD!C29)} -> 73224
A30: 28 | B30: =IF(B29=236,1,B29+1) -> 28 | C30: =IF(B29=236,C29+1,C29) -> 1 | D30: 33 | E30: =VLOOKUP(D30,[1]Hoja1!$C$2:$D$49697,2,0) -> CERVECERIA CUAUHTEMOC MOCTEZUMA SA DE CV | F30: CERVECERIA CUAUHTEMOC MOCTEZUMA SA DE CV | G30: MP-0246 | H30: TERMAMYL SC 4X PORRON 25 KG | I30: CERVEZA | J30: ROGELIO CURIEL | K30: 12.73 | L30: PRESUPUESTO | M30: {=INDEX(ACUMULADO!$J$5:$U$240,BD!B30,BD!C30)} -> 400 | N30: =IFERROR(O30/M30,0) -> 12.73 | O30: {=INDEX(ACUMULADO!$X$5:$AI$240,BD!B30,BD!C30)} -> 5092
A31: 29 | B31: =IF(B30=236,1,B30+1) -> 29 | C31: =IF(B30=236,C30+1,C30) -> 1 | D31: 337 | E31: =VLOOKUP(D31,[1]Hoja1!$C$2:$D$49697,2,0) -> CERVECERIA CUAUHTEMOC MOCTEZUMA SA DE CV | F31: CERVECERIA CUAUHTEMOC MOCTEZUMA SA DE CV | G31: MP-0044 | H31: ULTRAFLO MAX CONTENEDOR | I31: CERVEZA | J31: ROGELIO CURIEL | K31: 26.54 | L31: PRESUPUESTO | M31: {=INDEX(ACUMULADO!$J$5:$U$240,BD!B31,BD!C31)} -> 0 | N31: =IFERROR(O31/M31,0) -> 0 | O31: {=INDEX(ACUMULADO!$X$5:$AI$240,BD!B31,BD!C31)} -> 0
A32: 30 | B32: =IF(B31=236,1,B31+1) -> 30 | C32: =IF(B31=236,C31+1,C31) -> 1 | D32: 337 | E32: =VLOOKUP(D32,[1]Hoja1!$C$2:$D$49697,2,0) -> CERVECERIA CUAUHTEMOC MOCTEZUMA SA DE CV | F32: CERVECERIA CUAUHTEMOC MOCTEZUMA SA DE CV | G32: MP-0316 | H32: ATTENUZYME PRIME CONTENEDOR | I32: CERVEZA | J32: ROGELIO CURIEL | K32: 25.75 | L32: PRESUPUESTO | M32: {=INDEX(ACUMULADO!$J$5:$U$240,BD!B32,BD!C32)} -> 0 | N32: =IFERROR(O32/M32,0) -> 0 | O32: {=INDEX(ACUMULADO!$X$5:$AI$240,BD!B32,BD!C32)} -> 0
A33: 31 | B33: =IF(B32=236,1,B32+1) -> 31 | C33: =IF(B32=236,C32+1,C32) -> 1 | D33: 337 | E33: =VLOOKUP(D33,[1]Hoja1!$C$2:$D$49697,2,0) -> CERVECERIA CUAUHTEMOC MOCTEZUMA SA DE CV | F33: CERVECERIA CUAUHTEMOC MOCTEZUMA SA DE CV | G33: 169 | H33: CEREMIX PLUS MG | I33: CERVEZA | J33: ROGELIO CURIEL | K33: 16.9 | L33: PRESUPUESTO | M33: {=INDEX(ACUMULADO!$J$5:$U$240,BD!B33,BD!C33)} -> 0 | N33: =IFERROR(O33/M33,0) -> 0 | O33: {=INDEX(ACUMULADO!$X$5:$AI$240,BD!B33,BD!C33)} -> 0
A34: 32 | B34: =IF(B33=236,1,B33+1) -> 32 | C34: =IF(B33=236,C33+1,C33) -> 1 | D34: 337 | E34: =VLOOKUP(D34,[1]Hoja1!$C$2:$D$49697,2,0) -> CERVECERIA CUAUHTEMOC MOCTEZUMA SA DE CV | F34: CERVECERIA CUAUHTEMOC MOCTEZUMA SA DE CV | G34: CON-0343 | H34: TERMAMYL SC DS CONTENEDOR 1200 KG | I34: CERVEZA | J34: ROGELIO CURIEL | K34: 12.98 | L34: PRESUPUESTO | M34: {=INDEX(ACUMULADO!$J$5:$U$240,BD!B34,BD!C34)} -> 0 | N34: =IFERROR(O34/M34,0) -> 0 | O34: {=INDEX(ACUMULADO!$X$5:$AI$240,BD!B34,BD!C34)} -> 0
A35: 33 | B35: =IF(B34=236,1,B34+1) -> 33 | C35: =IF(B34=236,C34+1,C34) -> 1 | D35: 342 | E35: =VLOOKUP(D35,[1]Hoja1!$C$2:$D$49697,2,0) -> RED STRIPE | F35: RED STRIPE | G35: MP-0184 | H35: MATUREX PRO | I35: CERVEZA | J35: ROGELIO CURIEL | K35: 81.36 | L35: PRESUPUESTO | M35: {=INDEX(ACUMULADO!$J$5:$U$240,BD!B35,BD!C35)} -> 0 | N35: =IFERROR(O35/M35,0) -> 0 | O35: {=INDEX(ACUMULADO!$X$5:$AI$240,BD!B35,BD!C35)} -> 0
A36: 34 | B36: =IF(B35=236,1,B35+1) -> 34 | C36: =IF(B35=236,C35+1,C35) -> 1 | D36: 393 | E36: =VLOOKUP(D36,[1]Hoja1!$C$2:$D$49697,2,0) -> CERVECERIA CUAUHTEMOC MOCTEZUMA SA DE CV | F36: CERVECERIA CUAUHTEMOC MOCTEZUMA SA DE CV | G36: MP-0268 | H36: ULTRAFLO PRIME | I36: CERVEZA | J36: ROGELIO CURIEL | K36: 28.78 | L36: PRESUPUESTO | M36: {=INDEX(ACUMULADO!$J$5:$U$240,BD!B36,BD!C36)} -> 1100 | N36: =IFERROR(O36/M36,0) -> 28.78 | O36: {=INDEX(ACUMULADO!$X$5:$AI$240,BD!B36,BD!C36)} -> 31658
A37: 35 | B37: =IF(B36=236,1,B36+1) -> 35 | C37: =IF(B36=236,C36+1,C36) -> 1 | D37: 436 | E37: =VLOOKUP(D37,[1]Hoja1!$C$2:$D$49697,2,0) -> CERVECERIA PANAMA, S.A. | F37: CERVECERIA PANAMA, S.A. | G37: MP-0184 | H37: MATUREX PRO | I37: CERVEZA | J37: ROGELIO CURIEL | K37: 81.36 | L37: PRESUPUESTO | M37: {=INDEX(ACUMULADO!$J$5:$U$240,BD!B37,BD!C37)} -> 40 | N37: =IFERROR(O37/M37,0) -> 81.36 | O37: {=INDEX(ACUMULADO!$X$5:$AI$240,BD!B37,BD!C37)} -> 3254.4
A38: 36 | B38: =IF(B37=236,1,B37+1) -> 36 | C38: =IF(B37=236,C37+1,C37) -> 1 | D38: 500 | E38: =VLOOKUP(D38,[1]Hoja1!$C$2:$D$49697,2,0) -> HEINEKEN PERU SAC | F38: HEINEKEN PERU SAC | G38: POR-0352 | H38: ULTRAFLO MAX | I38: CERVEZA | J38: ROGELIO CURIEL | K38: 26.54 | L38: PRESUPUESTO | M38: {=INDEX(ACUMULADO!$J$5:$U$240,BD!B38,BD!C38)} -> 0 | N38: =IFERROR(O38/M38,0) -> 0 | O38: {=INDEX(ACUMULADO!$X$5:$AI$240,BD!B38,BD!C38)} -> 0
A39: 37 | B39: =IF(B38=236,1,B38+1) -> 37 | C39: =IF(B38=236,C38+1,C38) -> 1 | D39: 500 | E39: =VLOOKUP(D39,[1]Hoja1!$C$2:$D$49697,2,0) -> HEINEKEN PERU SAC | F39: HEINEKEN PERU SAC | G39: MP-0066 | H39: ATTENUZYME PRO | I39: CERVEZA | J39: ROGELIO CURIEL | K39: 13.6 | L39: PRESUPUESTO | M39: {=INDEX(ACUMULADO!$J$5:$U$240,BD!B39,BD!C39)} -> 50 | N39: =IFERROR(O39/M39,0) -> 13.6 | O39: {=INDEX(ACUMULADO!$X$5:$AI$240,BD!B39,BD!C39)} -> 680
A40: 38 | B40: =IF(B39=236,1,B39+1) -> 38 | C40: =IF(B39=236,C39+1,C39) -> 1 | D40: 500 | E40: =VLOOKUP(D40,[1]Hoja1!$C$2:$D$49697,2,0) -> HEINEKEN PERU SAC | F40: HEINEKEN PERU SAC | G40: MP-0246 | H40: TERMAMYL SC 4X PORRON 25 KG | I40: CERVEZA | J40: ROGELIO CURIEL | K40: 12.73 | L40: PRESUPUESTO | M40: {=INDEX(ACUMULADO!$J$5:$U$240,BD!B40,BD!C40)} -> 0 | N40: =IFERROR(O40/M40,0) -> 0 | O40: {=INDEX(ACUMULADO!$X$5:$AI$240,BD!B40,BD!C40)} -> 0
A41: 39 | B41: =IF(B40=236,1,B40+1) -> 39 | C41: =IF(B40=236,C40+1,C40) -> 1 | D41: 392 | E41: =VLOOKUP(D41,[1]Hoja1!$C$2:$D$49697,2,0) -> CIH INTERNATIONAL, S.A.R.L. | F41: CI CERVEZA GmbH. | G41: CON-0066 | H41: ATTENUZYME PRO | I41: CERVEZA | J41: ROGELIO CURIEL | K41: 18.32 | L41: PRESUPUESTO | M41: {=INDEX(ACUMULADO!$J$5:$U$240,BD!B41,BD!C41)} -> 0 | N41: =IFERROR(O41/M41,0) -> 0 | O41: {=INDEX(ACUMULADO!$X$5:$AI$240,BD!B41,BD!C41)} -> 0
...

Sheet ACUMULADO
A4: CODIGO | B4: CLAVE | C4: NOMBRE DEL CLIENTE | D4: CLAVE DEL PRODUCTO SKU | E4: PRODUCTO | F4: AREA | G4: VENDEDOR | H4: PRECIO UNITARIO EN DÓLARES | I4: TIPO | J4: ENERO | K4: FEBRERO | L4: MARZO | M4: ABRIL | N4: MAYO | O4: JUNIO | P4: JULIO | Q4: AGOSTO | R4: SEPTIEMBRE | S4: OCTUBRE | T4: NOVIEMBRE | U4: DICIEMBRE | V4: TOTAL | X4: ENERO | Y4: FEBRERO | Z4: MARZO | AA4: ABRIL | AB4: MAYO | AC4: JUNIO | AD4: JULIO | AE4: AGOSTO | AF4: SEPTIEMBRE | AG4: OCTUBRE | AH4: NOVIEMBRE | AI4: DICIEMBRE | AJ4: TOTAL
A5: 1 | B5: 28 | C5: CERVECERIA CUAUHTEMOC MOCTEZUMA SA DE CV | D5: MP-0308 | E5: ULTRAFLO PRIME CONTENEDOR | F5: CERVEZA | G5: ROGELIO CURIEL | H5: 28.78 | I5: PRESUPUESTO | K5: 2000 | N5: 2000 | Q5: 1000 | T5: 1000 | V5: 6000 | X5: 0 | Y5: 57560 | Z5: 0 | AA5: 0 | AB5: 57560 | AC5: 0 | AD5: 0 | AE5: 28780 | AF5: 0 | AG5: 0 | AH5: 28780 | AI5: 0 | AJ5: 172680
A6: 2 | B6: 28 | C6: CERVECERIA CUAUHTEMOC MOCTEZUMA SA DE CV | D6: MP-0316 | E6: ATTENUZYME PRIME CONTENEDOR | F6: CERVEZA | G6: ROGELIO CURIEL | H6: 25.75 | I6: PRESUPUESTO | J6: 2200 | K6: 2200 | L6: 2200 | M6: 2200 | N6: 2200 | O6: 2200 | P6: 2200 | Q6: 1100 | R6: 1100 | S6: 1100 | T6: 1100 | U6: 1100 | V6: 20900 | X6: 56650 | Y6: 56650 | Z6: 56650 | AA6: 56650 | AB6: 56650 | AC6: 56650 | AD6: 56650 | AE6: 28325 | AF6: 28325 | AG6: 28325 | AH6: 28325 | AI6: 28325 | AJ6: 538175
A7: 3 | B7: 28 | C7: CERVECERIA CUAUHTEMOC MOCTEZUMA SA DE CV | D7: 169 | E7: CEREMIX PLUS MG | F7: CERVEZA | G7: ROGELIO CURIEL | H7: 16.9 | I7: PRESUPUESTO | K7: 2200 | N7: 2000 | Q7: 2000 | T7: 2000 | V7: 8200 | X7: 0 | Y7: 37180 | Z7: 0 | AA7: 0 | AB7: 33800 | AC7: 0 | AD7: 0 | AE7: 33800 | AF7: 0 | AG7: 0 | AH7: 33800 | AI7: 0 | AJ7: 138580
A8: 4 | B8: 28 | C8: CERVECERIA CUAUHTEMOC MOCTEZUMA SA DE CV | D8: CON-0246 | E8: TERMAMYL SC 4X CONTENEDOR 1200 KG | F8: CERVEZA | G8: ROGELIO CURIEL | H8: 12.73 | I8: PRESUPUESTO | K8: 1200 | Q8: 1200 | V8: 2400 | X8: 0 | Y8: 15276 | Z8: 0 | AA8: 0 | AB8: 0 | AC8: 0 | AD8: 0 | AE8: 15276 | AF8: 0 | AG8: 0 | AH8: 0 | AI8: 0 | AJ8: 30552
A9: 5 | B9: 28 | C9: CERVECERIA CUAUHTEMOC MOCTEZUMA SA DE CV | D9: MP-0184 | E9: MATUREX PRO | F9: CERVEZA | G9: ROGELIO CURIEL | H9: 81.36 | I9: PRESUPUESTO | J9: 180 | L9: 180 | N9: 180 | P9: 170 | R9: 160 | T9: 160 | V9: 1030 | X9: 14644.8 | Y9: 0 | Z9: 14644.8 | AA9: 0 | AB9: 14644.8 | AC9: 0 | AD9: 13831.2 | AE9: 0 | AF9: 13017.6 | AG9: 0 | AH9: 13017.6 | AI9: 0 | AJ9: 83800.8
A10: 6 | B10: 29 | C10: CERVECERIA CUAUHTEMOC MOCTEZUMA SA DE CV | D10: MP-0268 | E10: ULTRAFLO PRIME | F10: CERVEZA | G10: ROGELIO CURIEL | H10: 28.78 | I10: PRESUPUESTO | J10: 475 | M10: 475 | P10: 475 | S10: 475 | V10: 1900 | X10: 13670.5 | Y10: 0 | Z10: 0 | AA10: 13670.5 | AB10: 0 | AC10: 0 | AD10: 13670.5 | AE10: 0 | AF10: 0 | AG10: 13670.5 | AH10: 0 | AI10: 0 | AJ10: 54682
A11: 7 | B11: 29 | C11: CERVECERIA CUAUHTEMOC MOCTEZUMA SA DE CV | D11: MP-0317 | E11: ATTENUZYME PRIME | F11: CERVEZA | G11: ROGELIO CURIEL | H11: 25.75 | I11: PRESUPUESTO | J11: 1600 | M11: 1600 | P11: 1600 | S11: 1600 | V11: 6400 | X11: 41200 | Y11: 0 | Z11: 0 | AA11: 41200 | AB11: 0 | AC11: 0 | AD11: 41200 | AE11: 0 | AF11: 0 | AG11: 41200 | AH11: 0 | AI11: 0 | AJ11: 164800
A12: 8 | B12: 29 | C12: CERVECERIA CUAUHTEMOC MOCTEZUMA SA DE CV | D12: 169 | E12: CEREMIX PLUS MG | F12: CERVEZA | G12: ROGELIO CURIEL | H12: 16.9 | I12: PRESUPUESTO | J12: 800 | M12: 800 | P12: 800 | S12: 600 | V12: 3000 | X12: 13520 | Y12: 0 | Z12: 0 | AA12: 13520 | AB12: 0 | AC12: 0 | AD12: 13520 | AE12: 0 | AF12: 0 | AG12: 10140 | AH12: 0 | AI12: 0 | AJ12: 50700
A13: 9 | B13: 29 | C13: CERVECERIA CUAUHTEMOC MOCTEZUMA SA DE CV | D13: MP-0184 | E13: MATUREX PRO | F13: CERVEZA | G13: ROGELIO CURIEL | H13: 81.36 | I13: PRESUPUESTO | J13: 60 | M13: 70 | P13: 70 | S13: 60 | V13: 260 | X13: 4881.6 | Y13: 0 | Z13: 0 | AA13: 5695.2 | AB13: 0 | AC13: 0 | AD13: 5695.2 | AE13: 0 | AF13: 0 | AG13: 4881.6 | AH13: 0 | AI13: 0 | AJ13: 21153.6
A14: 10 | B14: 29 | C14: CERVECERIA CUAUHTEMOC MOCTEZUMA SA DE CV | D14: MP-0246 | E14: TERMAMYL SC 4X PORRON 25 KG | F14: CERVEZA | G14: ROGELIO CURIEL | H14: 12.73 | I14: PRESUPUESTO | J14: 300 | M14: 300 | P14: 300 | S14: 300 | V14: 1200 | X14: 3819 | Y14: 0 | Z14: 0 | AA14: 3819 | AB14: 0 | AC14: 0 | AD14: 3819 | AE14: 0 | AF14: 0 | AG14: 3819 | AH14: 0 | AI14: 0 | AJ14: 15276
A15: 11 | B15: 30 | C15: CERVECERIA CUAUHTEMOC MOCTEZUMA SA DE CV | D15: MP-0268 | E15: ULTRAFLO PRIME | F15: CERVEZA | G15: ROGELIO CURIEL | H15: 28.78 | I15: PRESUPUESTO | K15: 400 | N15: 400 | Q15: 400 | V15: 1200 | X15: 0 | Y15: 11512 | Z15: 0 | AA15: 0 | AB15: 11512 | AC15: 0 | AD15: 0 | AE15: 11512 | AF15: 0 | AG15: 0 | AH15: 0 | AI15: 0 | AJ15: 34536
A16: 12 | B16: 30 | C16: CERVECERIA CUAUHTEMOC MOCTEZUMA SA DE CV | D16: MP-0317 | E16: ATTENUZYME PRIME | F16: CERVEZA | G16: ROGELIO CURIEL | H16: 25.75 | I16: PRESUPUESTO | K16: 1000 | N16: 1000 | Q16: 800 | T16: 600 | V16: 3400 | X16: 0 | Y16: 25750 | Z16: 0 | AA16: 0 | AB16: 25750 | AC16: 0 | AD16: 0 | AE16: 20600 | AF16: 0 | AG16: 0 | AH16: 15450 | AI16: 0 | AJ16: 87550
A17: 13 | B17: 30 | C17: CERVECERIA CUAUHTEMOC MOCTEZUMA SA DE CV | D17: 169 | E17: CEREMIX PLUS MG | F17: CERVEZA | G17: ROGELIO CURIEL | H17: 16.9 | I17: PRESUPUESTO | K17: 600 | N17: 600 | Q17: 600 | T17: 600 | V17: 2400 | X17: 0 | Y17: 10140 | Z17: 0 | AA17: 0 | AB17: 10140 | AC17: 0 | AD17: 0 | AE17: 10140 | AF17: 0 | AG17: 0 | AH17: 10140 | AI17: 0 | AJ17: 40560
A18: 14 | B18: 30 | C18: CERVECERIA CUAUHTEMOC MOCTEZUMA SA DE CV | D18: MP-0246 | E18: TERMAMYL SC 4X PORRON 25 KG | F18: CERVEZA | G18: ROGELIO CURIEL | H18: 12.73 | I18: PRESUPUESTO | Q18: 400 | V18: 400 | X18: 0 | Y18: 0 | Z18: 0 | AA18: 0 | AB18: 0 | AC18: 0 | AD18: 0 | AE18: 5092 | AF18: 0 | AG18: 0 | AH18: 0 | AI18: 0 | AJ18: 5092
A19: 15 | B19: 31 | C19: CERVECERIA CUAUHTEMOC MOCTEZUMA SA DE CV | D19: MP-0308 | E19: ULTRAFLO PRIME CONTENEDOR | F19: CERVEZA | G19: ROGELIO CURIEL | H19: 28.78 | I19: PRESUPUESTO | K19: 2000 | N19: 2000 | Q19: 1000 | T19: 1000 | V19: 6000 | X19: 0 | Y19: 57560 | Z19: 0 | AA19: 0 | AB19: 57560 | AC19: 0 | AD19: 0 | AE19: 28780 | AF19: 0 | AG19: 0 | AH19: 28780 | AI19: 0 | AJ19: 172680
A20: 16 | B20: 31 | C20: CERVECERIA CUAUHTEMOC MOCTEZUMA SA DE CV | D20: 169 | E20: CEREMIX PLUS MG | F20: CERVEZA | G20: ROGELIO CURIEL | H20: 16.9 | I20: PRESUPUESTO | K20: 2400 | N20: 2400 | Q20: 2400 | T20: 1200 | V20: 8400 | X20: 0 | Y20: 40560 | Z20: 0 | AA20: 0 | AB20: 40560 | AC20: 0 | AD20: 0 | AE20: 40560 | AF20: 0 | AG20: 0 | AH20: 20280 | AI20: 0 | AJ20: 141960
A21: 17 | B21: 31 | C21: CERVECERIA CUAUHTEMOC MOCTEZUMA SA DE CV | D21: MP-0184 | E21: MATUREX PRO | F21: CERVEZA | G21: ROGELIO CURIEL | H21: 81.36 | I21: PRESUPUESTO | K21: 840 | N21: 840 | Q21: 840 | T21: 840 | V21: 3360 | X21: 0 | Y21: 68342.4 | Z21: 0 | AA21: 0 | AB21: 68342.4 | AC21: 0 | AD21: 0 | AE21: 68342.4 | AF21: 0 | AG21: 0 | AH21: 68342.4 | AI21: 0 | AJ21: 273369.6
A22: 18 | B22: 31 | C22: CERVECERIA CUAUHTEMOC MOCTEZUMA SA DE CV | D22: CON-0246 | E22: TERMAMYL SC 4X CONTENEDOR 1200 KG | F22: CERVEZA | G22: ROGELIO CURIEL | H22: 12.73 | I22: PRESUPUESTO | K22: 1200 | N22: 1200 | Q22: 1200 | T22: 1200 | V22: 4800 | X22: 0 | Y22: 15276 | Z22: 0 | AA22: 0 | AB22: 15276 | AC22: 0 | AD22: 0 | AE22: 15276 | AF22: 0 | AG22: 0 | AH22: 15276 | AI22: 0 | AJ22: 61104
A23: 19 | B23: 32 | C23: CERVECERIA CUAUHTEMOC MOCTEZUMA SA DE CV | D23: MP-0044 | E23: ULTRAFLO MAX CONTENEDOR | F23: CERVEZA | G23: ROGELIO CURIEL | H23: 26.54 | I23: PRESUPUESTO | K23: 1000 | N23: 1000 | Q23: 1000 | T23: 1000 | V23: 4000 | X23: 0 | Y23: 26540 | Z23: 0 | AA23: 0 | AB23: 26540 | AC23: 0 | AD23: 0 | AE23: 26540 | AF23: 0 | AG23: 0 | AH23: 26540 | AI23: 0 | AJ23: 106160
A24: 20 | B24: 32 | C24: CERVECERIA CUAUHTEMOC MOCTEZUMA SA DE CV | D24: MP-0316 | E24: ATTENUZYME PRIME CONTENEDOR | F24: CERVEZA | G24: ROGELIO CURIEL | H24: 25.75 | I24: PRESUPUESTO | T24: 1100 | V24: 1100 | X24: 0 | Y24: 0 | Z24: 0 | AA24: 0 | AB24: 0 | AC24: 0 | AD24: 0 | AE24: 0 | AF24: 0 | AG24: 0 | AH24: 28325 | AI24: 0 | AJ24: 28325
A25: 21 | B25: 32 | C25: CERVECERIA CUAUHTEMOC MOCTEZUMA SA DE CV | D25: 169 | E25: CEREMIX PLUS MG | F25: CERVEZA | G25: ROGELIO CURIEL | H25: 16.9 | I25: PRESUPUESTO | K25: 720 | N25: 720 | Q25: 720 | T25: 720 | V25: 2880 | X25: 0 | Y25: 12168 | Z25: 0 | AA25: 0 | AB25: 12168 | AC25: 0 | AD25: 0 | AE25: 12168 | AF25: 0 | AG25: 0 | AH25: 12168 | AI25: 0 | AJ25: 48672
A26: 22 | B26: 32 | C26: CERVECERIA CUAUHTEMOC MOCTEZUMA SA DE CV | D26: MP-0184 | E26: MATUREX PRO | F26: CERVEZA | G26: ROGELIO CURIEL | H26: 81.36 | I26: PRESUPUESTO | Q26: 40 | V26: 40 | X26: 0 | Y26: 0 | Z26: 0 | AA26: 0 | AB26: 0 | AC26: 0 | AD26: 0 | AE26: 3254.4 | AF26: 0 | AG26: 0 | AH26: 0 | AI26: 0 | AJ26: 3254.4
A27: 23 | B27: 32 | C27: CERVECERIA CUAUHTEMOC MOCTEZUMA SA DE CV | D27: CON-0343 | E27: TERMAMYL SC DS CONTENEDOR 1200 KG | F27: CERVEZA | G27: ROGELIO CURIEL | H27: 12.98 | I27: PRESUPUESTO | N27: 1200 | Q27: 1200 | T27: 1200 | V27: 3600 | X27: 0 | Y27: 0 | Z27: 0 | AA27: 0 | AB27: 15576 | AC27: 0 | AD27: 0 | AE27: 15576 | AF27: 0 | AG27: 0 | AH27: 15576 | AI27: 0 | AJ27: 46728
A28: 24 | B28: 33 | C28: CERVECERIA CUAUHTEMOC MOCTEZUMA SA DE CV | D28: MP-0268 | E28: ULTRAFLO PRIME | F28: CERVEZA | G28: ROGELIO CURIEL | H28: 28.78 | I28: PRESUPUESTO | J28: 660 | M28: 660 | P28: 660 | S28: 660 | V28: 2640 | X28: 18994.8 | Y28: 0 | Z28: 0 | AA28: 18994.8 | AB28: 0 | AC28: 0 | AD28: 18994.8 | AE28: 0 | AF28: 0 | AG28: 18994.8 | AH28: 0 | AI28: 0 | AJ28: 75979.2
A29: 25 | B29: 33 | C29: CERVECERIA CUAUHTEMOC MOCTEZUMA SA DE CV | D29: MP-0317 | E29: ATTENUZYME PRIME | F29: CERVEZA | G29: ROGELIO CURIEL | H29: 25.75 | I29: PRESUPUESTO | J29: 2500 | M29: 3000 | P29: 3000 | S29: 2500 | V29: 11000 | X29: 64375 | Y29: 0 | Z29: 0 | AA29: 77250 | AB29: 0 | AC29: 0 | AD29: 77250 | AE29: 0 | AF29: 0 | AG29: 64375 | AH29: 0 | AI29: 0 | AJ29: 283250
A30: 26 | B30: 33 | C30: CERVECERIA CUAUHTEMOC MOCTEZUMA SA DE CV | D30: 169 | E30: CEREMIX PLUS MG | F30: CERVEZA | G30: ROGELIO CURIEL | H30: 16.9 | I30: PRESUPUESTO | J30: 1000 | M30: 800 | P30: 800 | S30: 800 | V30: 3400 | X30: 16900 | Y30: 0 | Z30: 0 | AA30: 13520 | AB30: 0 | AC30: 0 | AD30: 13520 | AE30: 0 | AF30: 0 | AG30: 13520 | AH30: 0 | AI30: 0 | AJ30: 57460
A31: 27 | B31: 33 | C31: CERVECERIA CUAUHTEMOC MOCTEZUMA SA DE CV | D31: MP-0184 | E31: MATUREX PRO | F31: CERVEZA | G31: ROGELIO CURIEL | H31: 81.36 | I31: PRESUPUESTO | J31: 900 | M31: 900 | P31: 900 | S31: 900 | V31: 3600 | X31: 73224 | Y31: 0 | Z31: 0 | AA31: 73224 | AB31: 0 | AC31: 0 | AD31: 73224 | AE31: 0 | AF31: 0 | AG31: 73224 | AH31: 0 | AI31: 0 | AJ31: 292896
A32: 28 | B32: 33 | C32: CERVECERIA CUAUHTEMOC MOCTEZUMA SA DE CV | D32: MP-0246 | E32: TERMAMYL SC 4X PORRON 25 KG | F32: CERVEZA | G32: ROGELIO CURIEL | H32: 12.73 | I32: PRESUPUESTO | J32: 400 | M32: 400 | P32: 350 | S32: 300 | V32: 1450 | X32: 5092 | Y32: 0 | Z32: 0 | AA32: 5092 | AB32: 0 | AC32: 0 | AD32: 4455.5 | AE32: 0 | AF32: 0 | AG32: 3819 | AH32: 0 | AI32: 0 | AJ32: 18458.5
A33: 29 | B33: 337 | C33: CERVECERIA CUAUHTEMOC MOCTEZUMA SA DE CV | D33: MP-0044 | E33: ULTRAFLO MAX CONTENEDOR | F33: CERVEZA | G33: ROGELIO CURIEL | H33: 26.54 | I33: PRESUPUESTO | K33: 1000 | M33: 1000 | P33: 1000 | S33: 1000 | V33: 4000 | X33: 0 | Y33: 26540 | Z33: 0 | AA33: 26540 | AB33: 0 | AC33: 0 | AD33: 26540 | AE33: 0 | AF33: 0 | AG33: 26540 | AH33: 0 | AI33: 0 | AJ33: 106160
A34: 30 | B34: 337 | C34: CERVECERIA CUAUHTEMOC MOCTEZUMA SA DE CV | D34: MP-0316 | E34: ATTENUZYME PRIME CONTENEDOR | F34: CERVEZA | G34: ROGELIO CURIEL | H34: 25.75 | I34: PRESUPUESTO | K34: 4400 | M34: 4400 | P34: 3300 | S34: 3300 | V34: 15400 | X34: 0 | Y34: 113300 | Z34: 0 | AA34: 113300 | AB34: 0 | AC34: 0 | AD34: 84975 | AE34: 0 | AF34: 0 | AG34: 84975 | AH34: 0 | AI34: 0 | AJ34: 396550
A35: 31 | B35: 337 | C35: CERVECERIA CUAUHTEMOC MOCTEZUMA SA DE CV | D35: 169 | E35: CEREMIX PLUS MG | F35: CERVEZA | G35: ROGELIO CURIEL | H35: 16.9 | I35: PRESUPUESTO | M35: 750 | P35: 750 | S35: 750 | V35: 2250 | X35: 0 | Y35: 0 | Z35: 0 | AA35: 12675 | AB35: 0 | AC35: 0 | AD35: 12675 | AE35: 0 | AF35: 0 | AG35: 12675 | AH35: 0 | AI35: 0 | AJ35: 38025
A36: 32 | B36: 337 | C36: CERVECERIA CUAUHTEMOC MOCTEZUMA SA DE CV | D36: CON-0343 | E36: TERMAMYL SC DS CONTENEDOR 1200 KG | F36: CERVEZA | G36: ROGELIO CURIEL | H36: 12.98 | I36: PRESUPUESTO | K36: 1200 | S36: 1200 | V36: 2400 | X36: 0 | Y36: 15576 | Z36: 0 | AA36: 0 | AB36: 0 | AC36: 0 | AD36: 0 | AE36: 0 | AF36: 0 | AG36: 15576 | AH36: 0 | AI36: 0 | AJ36: 31152
A37: 33 | B37: 342 | C37: RED STRIPE | D37: MP-0184 | E37: MATUREX PRO | F37: CERVEZA | G37: ROGELIO CURIEL | H37: 81.36 | I37: PRESUPUESTO | L37: 200 | R37: 250 | V37: 450 | X37: 0 | Y37: 0 | Z37: 16272 | AA37: 0 | AB37: 0 | AC37: 0 | AD37: 0 | AE37: 0 | AF37: 20340 | AG37: 0 | AH37: 0 | AI37: 0 | AJ37: 36612
A38: 34 | B38: 393 | C38: CERVECERIA CUAUHTEMOC MOCTEZUMA SA DE CV | D38: MP-0268 | E38: ULTRAFLO PRIME | F38: CERVEZA | G38: ROGELIO CURIEL | H38: 28.78 | I38: PRESUPUESTO | J38: 1100 | K38: 1100 | L38: 1100 | M38: 1100 | N38: 1100 | O38: 1100 | P38: 1100 | Q38: 1100 | R38: 1100 | S38: 1100 | T38: 1100 | U38: 1100 | V38: 13200 | X38: 31658 | Y38: 31658 | Z38: 31658 | AA38: 31658 | AB38: 31658 | AC38: 31658 | AD38: 31658 | AE38: 31658 | AF38: 31658 | AG38: 31658 | AH38: 31658 | AI38: 31658 | AJ38: 379896
A39: 35 | B39: 436 | C39: CERVECERIA PANAMA, S.A. | D39: MP-0184 | E39: MATUREX PRO | F39: CERVEZA | G39: ROGELIO CURIEL | H39: 81.36 | I39: PRESUPUESTO | J39: 40 | K39: 40 | L39: 40 | M39: 40 | N39: 40 | O39: 40 | P39: 40 | Q39: 40 | R39: 40 | S39: 40 | T39: 40 | U39: 40 | V39: 480 | X39: 3254.4 | Y39: 3254.4 | Z39: 3254.4 | AA39: 3254.4 | AB39: 3254.4 | AC39: 3254.4 | AD39: 3254.4 | AE39: 3254.4 | AF39: 3254.4 | AG39: 3254.4 | AH39: 3254.4 | AI39: 3254.4 | AJ39: 39052.8
A40: 36 | B40: 500 | C40: HEINEKEN PERU SAC | D40: POR-0352 | E40: ULTRAFLO MAX | F40: CERVEZA | G40: ROGELIO CURIEL | H40: 26.54 | I40: PRESUPUESTO | L40: 50 | S40: 50 | V40: 100 | X40: 0 | Y40: 0 | Z40: 1327 | AA40: 0 | AB40: 0 | AC40: 0 | AD40: 0 | AE40: 0 | AF40: 0 | AG40: 1327 | AH40: 0 | AI40: 0 | AJ40: 2654
A41: 37 | B41: 500 | C41: HEINEKEN PERU SAC | D41: MP-0066 | E41: ATTENUZYME PRO | F41: CERVEZA | G41: ROGELIO CURIEL | H41: 13.6 | I41: PRESUPUESTO | J41: 50 | N41: 50 | R41: 50 | U41: 50 | V41: 200 | X41: 680 | Y41: 0 | Z41: 0 | AA41: 0 | AB41: 680 | AC41: 0 | AD41: 0 | AE41: 0 | AF41: 680 | AG41: 0 | AH41: 0 | AI41: 680 | AJ41: 2720
A42: 38 | B42: 500 | C42: HEINEKEN PERU SAC | D42: MP-0246 | E42: TERMAMYL SC 4X PORRON 25 KG | F42: CERVEZA | G42: ROGELIO CURIEL | H42: 12.73 | I42: PRESUPUESTO | L42: 25 | S42: 25 | V42: 50 | X42: 0 | Y42: 0 | Z42: 318.25 | AA42: 0 | AB42: 0 | AC42: 0 | AD42: 0 | AE42: 0 | AF42: 0 | AG42: 318.25 | AH42: 0 | AI42: 0 | AJ42: 636.5
A43: 39 | B43: 392 | C43: CI CERVEZA GmbH. | D43: CON-0066 | E43: ATTENUZYME PRO | F43: CERVEZA | G43: ROGELIO CURIEL | H43: 18.32 | I43: PRESUPUESTO | K43: 8800 | L43: 16500 | N43: 16500 | O43: 13200 | Q43: 15400 | S43: 7700 | T43: 13200 | V43: 91300 | X43: 0 | Y43: 161216 | Z43: 302280 | AA43: 0 | AB43: 302280 | AC43: 241824 | AD43: 0 | AE43: 282128 | AF43: 0 | AG43: 141064 | AH43: 241824 | AI43: 0 | AJ43: 1672616
...

Sheet ROGELIO 2026
A3: CLAVE | B3: NOMBRE DEL CLIENTE | C3: CLAVE DEL PRODUCTO SKU | D3: PRODUCTO | E3: AREA | F3: VENDEDOR | G3: PRECIO UNITARIO EN DÓLARES | H3: TIPO | I3: ENERO | J3: FEBRERO | K3: MARZO | L3: ABRIL | M3: MAYO | N3: JUNIO | O3: JULIO | P3: AGOSTO | Q3: SEPTIEMBRE | R3: OCTUBRE | S3: NOVIEMBRE | T3: DICIEMBRE | U3: TOTAL | W3: ENERO | X3: FEBRERO | Y3: MARZO | Z3: ABRIL | AA3: MAYO | AB3: JUNIO | AC3: JULIO | AD3: AGOSTO | AE3: SEPTIEMBRE | AF3: OCTUBRE | AG3: NOVIEMBRE | AH3: DICIEMBRE | AI3: TOTAL | AJ3: TOTAL CLIENTE (PLANTA) | AK3: TOTAL CLIENTE (GLOBAL) | AL3: TOTAL INDUSTRIA
A4: =IF(ISERROR(VLOOKUP(B4,[2]CLIENTES!$C$2:$G$156,5,0)),"",(VLOOKUP(B4,[2]CLIENTES!$C$2:$G$156,5,0))) -> 28 | B4: CERVECERIA CUAUHTEMOC MOCTEZUMA SA DE CV | C4: MP-0308 | D4: ULTRAFLO PRIME CONTENEDOR | E4: CERVEZA | F4: ROGELIO CURIEL | G4: 28.78 | H4: PRESUPUESTO | J4: 2000 | M4: 2000 | P4: 1000 | S4: 1000 | U4: =SUM(I4:T4) -> 6000 | W4: =+$G4*I4 -> 0 | X4: =+$G4*J4 -> 57560 | Y4: =+$G4*K4 -> 0 | Z4: =+$G4*L4 -> 0 | AA4: =+$G4*M4 -> 57560 | AB4: =+$G4*N4 -> 0 | AC4: =+$G4*O4 -> 0 | AD4: =+$G4*P4 -> 28780 | ... AH4: =+$G4*T4 -> 0 | AI4: =SUM(W4:AH4) -> 172680
A5: =IF(ISERROR(VLOOKUP(B5,[2]CLIENTES!$C$2:$G$156,5,0)),"",(VLOOKUP(B5,[2]CLIENTES!$C$2:$G$156,5,0))) -> 28 | B5: CERVECERIA CUAUHTEMOC MOCTEZUMA SA DE CV | C5: MP-0316 | D5: ATTENUZYME PRIME CONTENEDOR | E5: CERVEZA | F5: ROGELIO CURIEL | G5: 25.75 | H5: PRESUPUESTO | I5: 2200 | J5: 2200 | K5: 2200 | L5: 2200 | M5: 2200 | N5: 2200 | O5: 2200 | P5: 1100 | Q5: 1100 | R5: 1100 | S5: 1100 | T5: 1100 | U5: =SUM(I5:T5) -> 20900 | W5: =+$G5*I5 -> 56650 | X5: =+$G5*J5 -> 56650 | Y5: =+$G5*K5 -> 56650 | Z5: =+$G5*L5 -> 56650 | AA5: =+$G5*M5 -> 56650 | AB5: =+$G5*N5 -> 56650 | AC5: =+$G5*O5 -> 56650 | AD5: =+$G5*P5 -> 28325 | ... AH5: =+$G5*T5 -> 28325 | AI5: =SUM(W5:AH5) -> 538175
A6: =IF(ISERROR(VLOOKUP(B6,[2]CLIENTES!$C$2:$G$156,5,0)),"",(VLOOKUP(B6,[2]CLIENTES!$C$2:$G$156,5,0))) -> 28 | B6: CERVECERIA CUAUHTEMOC MOCTEZUMA SA DE CV | C6: =IF(ISERROR(VLOOKUP(D6,[2]PRODUCTOS!$B$2:$J$800,9,0)),"",(VLOOKUP(D6,[2]PRODUCTOS!$B$2:$J$800,9,0))) -> 169 | D6: CEREMIX PLUS MG | E6: CERVEZA | F6: ROGELIO CURIEL | G6: 16.9 | H6: PRESUPUESTO | J6: 2200 | M6: 2000 | P6: 2000 | S6: 2000 | U6: =SUM(I6:T6) -> 8200 | W6: =+$G6*I6 -> 0 | X6: =+$G6*J6 -> 37180 | Y6: =+$G6*K6 -> 0 | Z6: =+$G6*L6 -> 0 | AA6: =+$G6*M6 -> 33800 | AB6: =+$G6*N6 -> 0 | AC6: =+$G6*O6 -> 0 | AD6: =+$G6*P6 -> 33800 | ... AH6: =+$G6*T6 -> 0 | AI6: =SUM(W6:AH6) -> 138580
A7: =IF(ISERROR(VLOOKUP(B7,[2]CLIENTES!$C$2:$G$156,5,0)),"",(VLOOKUP(B7,[2]CLIENTES!$C$2:$G$156,5,0))) -> 28 | B7: CERVECERIA CUAUHTEMOC MOCTEZUMA SA DE CV | C7: CON-0246 | D7: TERMAMYL SC 4X CONTENEDOR 1200 KG | E7: CERVEZA | F7: ROGELIO CURIEL | G7: 12.73 | H7: PRESUPUESTO | J7: 1200 | P7: 1200 | U7: =SUM(I7:T7) -> 2400 | W7: =+$G7*I7 -> 0 | X7: =+$G7*J7 -> 15276 | Y7: =+$G7*K7 -> 0 | Z7: =+$G7*L7 -> 0 | AA7: =+$G7*M7 -> 0 | AB7: =+$G7*N7 -> 0 | AC7: =+$G7*O7 -> 0 | AD7: =+$G7*P7 -> 15276 | ... AH7: =+$G7*T7 -> 0 | AI7: =SUM(W7:AH7) -> 30552
A8: =IF(ISERROR(VLOOKUP(B8,[2]CLIENTES!$C$2:$G$156,5,0)),"",(VLOOKUP(B8,[2]CLIENTES!$C$2:$G$156,5,0))) -> 28 | B8: CERVECERIA CUAUHTEMOC MOCTEZUMA SA DE CV | C8: MP-0184 | D8: MATUREX PRO | E8: CERVEZA | F8: ROGELIO CURIEL | G8: 81.36 | H8: PRESUPUESTO | I8: 180 | K8: 180 | M8: 180 | O8: 170 | Q8: 160 | S8: 160 | U8: =SUM(I8:T8) -> 1030 | W8: =+$G8*I8 -> 14644.8 | X8: =+$G8*J8 -> 0 | Y8: =+$G8*K8 -> 14644.8 | Z8: =+$G8*L8 -> 0 | AA8: =+$G8*M8 -> 14644.8 | AB8: =+$G8*N8 -> 0 | AC8: =+$G8*O8 -> 13831.2 | AD8: =+$G8*P8 -> 0 | ... AH8: =+$G8*T8 -> 0 | AI8: =SUM(W8:AH8) -> 83800.8 | AJ8: =SUM(AI4:AI8) -> 963787.8
A9: 29 | B9: CERVECERIA CUAUHTEMOC MOCTEZUMA SA DE CV | C9: MP-0268 | D9: ULTRAFLO PRIME | E9: CERVEZA | F9: ROGELIO CURIEL | G9: 28.78 | H9: PRESUPUESTO | I9: 475 | L9: 475 | O9: 475 | R9: 475 | U9: =SUM(I9:T9) -> 1900 | W9: =+$G9*I9 -> 13670.5 | X9: =+$G9*J9 -> 0 | Y9: =+$G9*K9 -> 0 | Z9: =+$G9*L9 -> 13670.5 | AA9: =+$G9*M9 -> 0 | AB9: =+$G9*N9 -> 0 | AC9: =+$G9*O9 -> 13670.5 | AD9: =+$G9*P9 -> 0 | ... AH9: =+$G9*T9 -> 0 | AI9: =SUM(W9:AH9) -> 54682
A10: 29 | B10: CERVECERIA CUAUHTEMOC MOCTEZUMA SA DE CV | C10: MP-0317 | D10: ATTENUZYME PRIME | E10: CERVEZA | F10: ROGELIO CURIEL | G10: 25.75 | H10: PRESUPUESTO | I10: 1600 | L10: 1600 | O10: 1600 | R10: 1600 | U10: =SUM(I10:T10) -> 6400 | W10: =+$G10*I10 -> 41200 | X10: =+$G10*J10 -> 0 | Y10: =+$G10*K10 -> 0 | Z10: =+$G10*L10 -> 41200 | AA10: =+$G10*M10 -> 0 | AB10: =+$G10*N10 -> 0 | AC10: =+$G10*O10 -> 41200 | AD10: =+$G10*P10 -> 0 | ... AH10: =+$G10*T10 -> 0 | AI10: =SUM(W10:AH10) -> 164800
A11: 29 | B11: CERVECERIA CUAUHTEMOC MOCTEZUMA SA DE CV | C11: =IF(ISERROR(VLOOKUP(D11,[2]PRODUCTOS!$B$2:$J$800,9,0)),"",(VLOOKUP(D11,[2]PRODUCTOS!$B$2:$J$800,9,0))) -> 169 | D11: CEREMIX PLUS MG | E11: CERVEZA | F11: ROGELIO CURIEL | G11: 16.9 | H11: PRESUPUESTO | I11: 800 | L11: 800 | O11: 800 | R11: 600 | U11: =SUM(I11:T11) -> 3000 | W11: =+$G11*I11 -> 13520 | X11: =+$G11*J11 -> 0 | Y11: =+$G11*K11 -> 0 | Z11: =+$G11*L11 -> 13520 | AA11: =+$G11*M11 -> 0 | AB11: =+$G11*N11 -> 0 | AC11: =+$G11*O11 -> 13520 | AD11: =+$G11*P11 -> 0 | ... AH11: =+$G11*T11 -> 0 | AI11: =SUM(W11:AH11) -> 50700
A12: 29 | B12: CERVECERIA CUAUHTEMOC MOCTEZUMA SA DE CV | C12: MP-0184 | D12: MATUREX PRO | E12: CERVEZA | F12: ROGELIO CURIEL | G12: 81.36 | H12: PRESUPUESTO | I12: 60 | L12: 70 | O12: 70 | R12: 60 | U12: =SUM(I12:T12) -> 260 | W12: =+$G12*I12 -> 4881.6 | X12: =+$G12*J12 -> 0 | Y12: =+$G12*K12 -> 0 | Z12: =+$G12*L12 -> 5695.2 | AA12: =+$G12*M12 -> 0 | AB12: =+$G12*N12 -> 0 | AC12: =+$G12*O12 -> 5695.2 | AD12: =+$G12*P12 -> 0 | ... AH12: =+$G12*T12 -> 0 | AI12: =SUM(W12:AH12) -> 21153.6
A13: 29 | B13: CERVECERIA CUAUHTEMOC MOCTEZUMA SA DE CV | C13: MP-0246 | D13: TERMAMYL SC 4X PORRON 25 KG | E13: CERVEZA | F13: ROGELIO CURIEL | G13: 12.73 | H13: PRESUPUESTO | I13: 300 | L13: 300 | O13: 300 | R13: 300 | U13: =SUM(I13:T13) -> 1200 | W13: =+$G13*I13 -> 3819 | X13: =+$G13*J13 -> 0 | Y13: =+$G13*K13 -> 0 | Z13: =+$G13*L13 -> 3819 | AA13: =+$G13*M13 -> 0 | AB13: =+$G13*N13 -> 0 | AC13: =+$G13*O13 -> 3819 | AD13: =+$G13*P13 -> 0 | ... AH13: =+$G13*T13 -> 0 | AI13: =SUM(W13:AH13) -> 15276 | AJ13: =SUM(AI9:AI13) -> 306611.6
A14: 30 | B14: CERVECERIA CUAUHTEMOC MOCTEZUMA SA DE CV | C14: MP-0268 | D14: ULTRAFLO PRIME | E14: CERVEZA | F14: ROGELIO CURIEL | G14: 28.78 | H14: PRESUPUESTO | J14: 400 | M14: 400 | P14: 400 | U14: =SUM(I14:T14) -> 1200 | W14: =+$G14*I14 -> 0 | X14: =+$G14*J14 -> 11512 | Y14: =+$G14*K14 -> 0 | Z14: =+$G14*L14 -> 0 | AA14: =+$G14*M14 -> 11512 | AB14: =+$G14*N14 -> 0 | AC14: =+$G14*O14 -> 0 | AD14: =+$G14*P14 -> 11512 | ... AH14: =+$G14*T14 -> 0 | AI14: =SUM(W14:AH14) -> 34536
A15: 30 | B15: CERVECERIA CUAUHTEMOC MOCTEZUMA SA DE CV | C15: MP-0317 | D15: ATTENUZYME PRIME | E15: CERVEZA | F15: ROGELIO CURIEL | G15: 25.75 | H15: PRESUPUESTO | J15: 1000 | M15: 1000 | P15: 800 | S15: 600 | U15: =SUM(I15:T15) -> 3400 | W15: =+$G15*I15 -> 0 | X15: =+$G15*J15 -> 25750 | Y15: =+$G15*K15 -> 0 | Z15: =+$G15*L15 -> 0 | AA15: =+$G15*M15 -> 25750 | AB15: =+$G15*N15 -> 0 | AC15: =+$G15*O15 -> 0 | AD15: =+$G15*P15 -> 20600 | ... AH15: =+$G15*T15 -> 0 | AI15: =SUM(W15:AH15) -> 87550
A16: 30 | B16: CERVECERIA CUAUHTEMOC MOCTEZUMA SA DE CV | C16: =IF(ISERROR(VLOOKUP(D16,[2]PRODUCTOS!$B$2:$J$800,9,0)),"",(VLOOKUP(D16,[2]PRODUCTOS!$B$2:$J$800,9,0))) -> 169 | D16: CEREMIX PLUS MG | E16: CERVEZA | F16: ROGELIO CURIEL | G16: 16.9 | H16: PRESUPUESTO | J16: 600 | M16: 600 | P16: 600 | S16: 600 | U16: =SUM(I16:T16) -> 2400 | W16: =+$G16*I16 -> 0 | X16: =+$G16*J16 -> 10140 | Y16: =+$G16*K16 -> 0 | Z16: =+$G16*L16 -> 0 | AA16: =+$G16*M16 -> 10140 | AB16: =+$G16*N16 -> 0 | AC16: =+$G16*O16 -> 0 | AD16: =+$G16*P16 -> 10140 | ... AH16: =+$G16*T16 -> 0 | AI16: =SUM(W16:AH16) -> 40560
A17: 30 | B17: CERVECERIA CUAUHTEMOC MOCTEZUMA SA DE CV | C17: MP-0246 | D17: TERMAMYL SC 4X PORRON 25 KG | E17: CERVEZA | F17: ROGELIO CURIEL | G17: 12.73 | H17: PRESUPUESTO | P17: 400 | U17: =SUM(I17:T17) -> 400 | W17: =+$G17*I17 -> 0 | X17: =+$G17*J17 -> 0 | Y17: =+$G17*K17 -> 0 | Z17: =+$G17*L17 -> 0 | AA17: =+$G17*M17 -> 0 | AB17: =+$G17*N17 -> 0 | AC17: =+$G17*O17 -> 0 | AD17: =+$G17*P17 -> 5092 | ... AH17: =+$G17*T17 -> 0 | AI17: =SUM(W17:AH17) -> 5092 | AJ17: =SUM(AI14:AI17) -> 167738
A18: 31 | B18: CERVECERIA CUAUHTEMOC MOCTEZUMA SA DE CV | C18: MP-0308 | D18: ULTRAFLO PRIME CONTENEDOR | E18: CERVEZA | F18: ROGELIO CURIEL | G18: 28.78 | H18: PRESUPUESTO | J18: 2000 | M18: 2000 | P18: 1000 | S18: 1000 | U18: =SUM(I18:T18) -> 6000 | W18: =+$G18*I18 -> 0 | X18: =+$G18*J18 -> 57560 | Y18: =+$G18*K18 -> 0 | Z18: =+$G18*L18 -> 0 | AA18: =+$G18*M18 -> 57560 | AB18: =+$G18*N18 -> 0 | AC18: =+$G18*O18 -> 0 | AD18: =+$G18*P18 -> 28780 | ... AH18: =+$G18*T18 -> 0 | AI18: =SUM(W18:AH18) -> 172680
A19: 31 | B19: CERVECERIA CUAUHTEMOC MOCTEZUMA SA DE CV | C19: =IF(ISERROR(VLOOKUP(D19,[2]PRODUCTOS!$B$2:$J$800,9,0)),"",(VLOOKUP(D19,[2]PRODUCTOS!$B$2:$J$800,9,0))) -> 169 | D19: CEREMIX PLUS MG | E19: CERVEZA | F19: ROGELIO CURIEL | G19: 16.9 | H19: PRESUPUESTO | J19: 2400 | M19: 2400 | P19: 2400 | S19: 1200 | U19: =SUM(I19:T19) -> 8400 | W19: =+$G19*I19 -> 0 | X19: =+$G19*J19 -> 40560 | Y19: =+$G19*K19 -> 0 | Z19: =+$G19*L19 -> 0 | AA19: =+$G19*M19 -> 40560 | AB19: =+$G19*N19 -> 0 | AC19: =+$G19*O19 -> 0 | AD19: =+$G19*P19 -> 40560 | ... AH19: =+$G19*T19 -> 0 | AI19: =SUM(W19:AH19) -> 141960
A20: 31 | B20: CERVECERIA CUAUHTEMOC MOCTEZUMA SA DE CV | C20: MP-0184 | D20: MATUREX PRO | E20: CERVEZA | F20: ROGELIO CURIEL | G20: 81.36 | H20: PRESUPUESTO | J20: 840 | M20: 840 | P20: 840 | S20: 840 | U20: =SUM(I20:T20) -> 3360 | W20: =+$G20*I20 -> 0 | X20: =+$G20*J20 -> 68342.4 | Y20: =+$G20*K20 -> 0 | Z20: =+$G20*L20 -> 0 | AA20: =+$G20*M20 -> 68342.4 | AB20: =+$G20*N20 -> 0 | AC20: =+$G20*O20 -> 0 | AD20: =+$G20*P20 -> 68342.4 | ... AH20: =+$G20*T20 -> 0 | AI20: =SUM(W20:AH20) -> 273369.6
A21: 31 | B21: CERVECERIA CUAUHTEMOC MOCTEZUMA SA DE CV | C21: CON-0246 | D21: TERMAMYL SC 4X CONTENEDOR 1200 KG | E21: CERVEZA | F21: ROGELIO CURIEL | G21: 12.73 | H21: PRESUPUESTO | J21: 1200 | M21: 1200 | P21: 1200 | S21: 1200 | U21: =SUM(I21:T21) -> 4800 | W21: =+$G21*I21 -> 0 | X21: =+$G21*J21 -> 15276 | Y21: =+$G21*K21 -> 0 | Z21: =+$G21*L21 -> 0 | AA21: =+$G21*M21 -> 15276 | AB21: =+$G21*N21 -> 0 | AC21: =+$G21*O21 -> 0 | AD21: =+$G21*P21 -> 15276 | ... AH21: =+$G21*T21 -> 0 | AI21: =SUM(W21:AH21) -> 61104 | AJ21: =SUM(AI18:AI21) -> 649113.6
A22: 32 | B22: CERVECERIA CUAUHTEMOC MOCTEZUMA SA DE CV | C22: =IF(ISERROR(VLOOKUP(D22,[2]PRODUCTOS!$B$2:$J$800,9,0)),"",(VLOOKUP(D22,[2]PRODUCTOS!$B$2:$J$800,9,0))) -> MP-0044 | D22: ULTRAFLO MAX CONTENEDOR | E22: CERVEZA | F22: ROGELIO CURIEL | G22: 26.54 | H22: PRESUPUESTO | J22: 1000 | M22: 1000 | P22: 1000 | S22: 1000 | U22: =SUM(I22:T22) -> 4000 | W22: =+$G22*I22 -> 0 | X22: =+$G22*J22 -> 26540 | Y22: =+$G22*K22 -> 0 | Z22: =+$G22*L22 -> 0 | AA22: =+$G22*M22 -> 26540 | AB22: =+$G22*N22 -> 0 | AC22: =+$G22*O22 -> 0 | AD22: =+$G22*P22 -> 26540 | ... AH22: =+$G22*T22 -> 0 | AI22: =SUM(W22:AH22) -> 106160
A23: 32 | B23: CERVECERIA CUAUHTEMOC MOCTEZUMA SA DE CV | C23: MP-0316 | D23: ATTENUZYME PRIME CONTENEDOR | E23: CERVEZA | F23: ROGELIO CURIEL | G23: 25.75 | H23: PRESUPUESTO | S23: 1100 | U23: =SUM(I23:T23) -> 1100 | W23: =+$G23*I23 -> 0 | X23: =+$G23*J23 -> 0 | Y23: =+$G23*K23 -> 0 | Z23: =+$G23*L23 -> 0 | AA23: =+$G23*M23 -> 0 | AB23: =+$G23*N23 -> 0 | AC23: =+$G23*O23 -> 0 | AD23: =+$G23*P23 -> 0 | ... AH23: =+$G23*T23 -> 0 | AI23: =SUM(W23:AH23) -> 28325
A24: 32 | B24: CERVECERIA CUAUHTEMOC MOCTEZUMA SA DE CV | C24: =IF(ISERROR(VLOOKUP(D24,[2]PRODUCTOS!$B$2:$J$800,9,0)),"",(VLOOKUP(D24,[2]PRODUCTOS!$B$2:$J$800,9,0))) -> 169 | D24: CEREMIX PLUS MG | E24: CERVEZA | F24: ROGELIO CURIEL | G24: 16.9 | H24: PRESUPUESTO | J24: 720 | M24: 720 | P24: 720 | S24: 720 | U24: =SUM(I24:T24) -> 2880 | W24: =+$G24*I24 -> 0 | X24: =+$G24*J24 -> 12168 | Y24: =+$G24*K24 -> 0 | Z24: =+$G24*L24 -> 0 | AA24: =+$G24*M24 -> 12168 | AB24: =+$G24*N24 -> 0 | AC24: =+$G24*O24 -> 0 | AD24: =+$G24*P24 -> 12168 | ... AH24: =+$G24*T24 -> 0 | AI24: =SUM(W24:AH24) -> 48672
A25: 32 | B25: CERVECERIA CUAUHTEMOC MOCTEZUMA SA DE CV | C25: MP-0184 | D25: MATUREX PRO | E25: CERVEZA | F25: ROGELIO CURIEL | G25: 81.36 | H25: PRESUPUESTO | P25: 40 | U25: =SUM(I25:T25) -> 40 | W25: =+$G25*I25 -> 0 | X25: =+$G25*J25 -> 0 | Y25: =+$G25*K25 -> 0 | Z25: =+$G25*L25 -> 0 | AA25: =+$G25*M25 -> 0 | AB25: =+$G25*N25 -> 0 | AC25: =+$G25*O25 -> 0 | AD25: =+$G25*P25 -> 3254.4 | ... AH25: =+$G25*T25 -> 0 | AI25: =SUM(W25:AH25) -> 3254.4
A26: 32 | B26: CERVECERIA CUAUHTEMOC MOCTEZUMA SA DE CV | C26: CON-0343 | D26: TERMAMYL SC DS CONTENEDOR 1200 KG | E26: CERVEZA | F26: ROGELIO CURIEL | G26: 12.98 | H26: PRESUPUESTO | M26: 1200 | P26: 1200 | S26: 1200 | U26: =SUM(I26:T26) -> 3600 | W26: =+$G26*I26 -> 0 | X26: =+$G26*J26 -> 0 | Y26: =+$G26*K26 -> 0 | Z26: =+$G26*L26 -> 0 | AA26: =+$G26*M26 -> 15576 | AB26: =+$G26*N26 -> 0 | AC26: =+$G26*O26 -> 0 | AD26: =+$G26*P26 -> 15576 | ... AH26: =+$G26*T26 -> 0 | AI26: =SUM(W26:AH26) -> 46728 | AJ26: =SUM(AI22:AI26) -> 233139.4
A27: 33 | B27: CERVECERIA CUAUHTEMOC MOCTEZUMA SA DE CV | C27: MP-0268 | D27: ULTRAFLO PRIME | E27: CERVEZA | F27: ROGELIO CURIEL | G27: 28.78 | H27: PRESUPUESTO | I27: 660 | L27: 660 | O27: 660 | R27: 660 | U27: =SUM(I27:T27) -> 2640 | W27: =+$G27*I27 -> 18994.8 | X27: =+$G27*J27 -> 0 | Y27: =+$G27*K27 -> 0 | Z27: =+$G27*L27 -> 18994.8 | AA27: =+$G27*M27 -> 0 | AB27: =+$G27*N27 -> 0 | AC27: =+$G27*O27 -> 18994.8 | AD27: =+$G27*P27 -> 0 | ... AH27: =+$G27*T27 -> 0 | AI27: =SUM(W27:AH27) -> 75979.2
A28: 33 | B28: CERVECERIA CUAUHTEMOC MOCTEZUMA SA DE CV | C28: MP-0317 | D28: ATTENUZYME PRIME | E28: CERVEZA | F28: ROGELIO CURIEL | G28: 25.75 | H28: PRESUPUESTO | I28: 2500 | L28: 3000 | O28: 3000 | R28: 2500 | U28: =SUM(I28:T28) -> 11000 | W28: =+$G28*I28 -> 64375 | X28: =+$G28*J28 -> 0 | Y28: =+$G28*K28 -> 0 | Z28: =+$G28*L28 -> 77250 | AA28: =+$G28*M28 -> 0 | AB28: =+$G28*N28 -> 0 | AC28: =+$G28*O28 -> 77250 | AD28: =+$G28*P28 -> 0 | ... AH28: =+$G28*T28 -> 0 | AI28: =SUM(W28:AH28) -> 283250
A29: 33 | B29: CERVECERIA CUAUHTEMOC MOCTEZUMA SA DE CV | C29: =IF(ISERROR(VLOOKUP(D29,[2]PRODUCTOS!$B$2:$J$800,9,0)),"",(VLOOKUP(D29,[2]PRODUCTOS!$B$2:$J$800,9,0))) -> 169 | D29: CEREMIX PLUS MG | E29: CERVEZA | F29: ROGELIO CURIEL | G29: 16.9 | H29: PRESUPUESTO | I29: 1000 | L29: 800 | O29: 800 | R29: 800 | U29: =SUM(I29:T29) -> 3400 | W29: =+$G29*I29 -> 16900 | X29: =+$G29*J29 -> 0 | Y29: =+$G29*K29 -> 0 | Z29: =+$G29*L29 -> 13520 | AA29: =+$G29*M29 -> 0 | AB29: =+$G29*N29 -> 0 | AC29: =+$G29*O29 -> 13520 | AD29: =+$G29*P29 -> 0 | ... AH29: =+$G29*T29 -> 0 | AI29: =SUM(W29:AH29) -> 57460
A30: 33 | B30: CERVECERIA CUAUHTEMOC MOCTEZUMA SA DE CV | C30: MP-0184 | D30: MATUREX PRO | E30: CERVEZA | F30: ROGELIO CURIEL | G30: 81.36 | H30: PRESUPUESTO | I30: 900 | L30: 900 | O30: 900 | R30: 900 | U30: =SUM(I30:T30) -> 3600 | W30: =+$G30*I30 -> 73224 | X30: =+$G30*J30 -> 0 | Y30: =+$G30*K30 -> 0 | Z30: =+$G30*L30 -> 73224 | AA30: =+$G30*M30 -> 0 | AB30: =+$G30*N30 -> 0 | AC30: =+$G30*O30 -> 73224 | AD30: =+$G30*P30 -> 0 | ... AH30: =+$G30*T30 -> 0 | AI30: =SUM(W30:AH30) -> 292896
A31: 33 | B31: CERVECERIA CUAUHTEMOC MOCTEZUMA SA DE CV | C31: MP-0246 | D31: TERMAMYL SC 4X PORRON 25 KG | E31: CERVEZA | F31: ROGELIO CURIEL | G31: 12.73 | H31: PRESUPUESTO | I31: 400 | L31: 400 | O31: 350 | R31: 300 | U31: =SUM(I31:T31) -> 1450 | W31: =+$G31*I31 -> 5092 | X31: =+$G31*J31 -> 0 | Y31: =+$G31*K31 -> 0 | Z31: =+$G31*L31 -> 5092 | AA31: =+$G31*M31 -> 0 | AB31: =+$G31*N31 -> 0 | AC31: =+$G31*O31 -> 4455.5 | AD31: =+$G31*P31 -> 0 | ... AH31: =+$G31*T31 -> 0 | AI31: =SUM(W31:AH31) -> 18458.5 | AJ31: =SUM(AI27:AI31) -> 728043.7
A32: 337 | B32: CERVECERIA CUAUHTEMOC MOCTEZUMA SA DE CV | C32: =IF(ISERROR(VLOOKUP(D32,[2]PRODUCTOS!$B$2:$J$800,9,0)),"",(VLOOKUP(D32,[2]PRODUCTOS!$B$2:$J$800,9,0))) -> MP-0044 | D32: ULTRAFLO MAX CONTENEDOR | E32: CERVEZA | F32: ROGELIO CURIEL | G32: 26.54 | H32: PRESUPUESTO | J32: 1000 | L32: 1000 | O32: 1000 | R32: 1000 | U32: =SUM(I32:T32) -> 4000 | W32: =+$G32*I32 -> 0 | X32: =+$G32*J32 -> 26540 | Y32: =+$G32*K32 -> 0 | Z32: =+$G32*L32 -> 26540 | AA32: =+$G32*M32 -> 0 | AB32: =+$G32*N32 -> 0 | AC32: =+$G32*O32 -> 26540 | AD32: =+$G32*P32 -> 0 | ... AH32: =+$G32*T32 -> 0 | AI32: =SUM(W32:AH32) -> 106160
A33: 337 | B33: CERVECERIA CUAUHTEMOC MOCTEZUMA SA DE CV | C33: MP-0316 | D33: ATTENUZYME PRIME CONTENEDOR | E33: CERVEZA | F33: ROGELIO CURIEL | G33: 25.75 | H33: PRESUPUESTO | J33: 4400 | L33: 4400 | O33: 3300 | R33: 3300 | U33: =SUM(I33:T33) -> 15400 | W33: =+$G33*I33 -> 0 | X33: =+$G33*J33 -> 113300 | Y33: =+$G33*K33 -> 0 | Z33: =+$G33*L33 -> 113300 | AA33: =+$G33*M33 -> 0 | AB33: =+$G33*N33 -> 0 | AC33: =+$G33*O33 -> 84975 | AD33: =+$G33*P33 -> 0 | ... AH33: =+$G33*T33 -> 0 | AI33: =SUM(W33:AH33) -> 396550
A34: 337 | B34: CERVECERIA CUAUHTEMOC MOCTEZUMA SA DE CV | C34: =IF(ISERROR(VLOOKUP(D34,[2]PRODUCTOS!$B$2:$J$800,9,0)),"",(VLOOKUP(D34,[2]PRODUCTOS!$B$2:$J$800,9,0))) -> 169 | D34: CEREMIX PLUS MG | E34: CERVEZA | F34: ROGELIO CURIEL | G34: 16.9 | H34: PRESUPUESTO | L34: 750 | O34: 750 | R34: 750 | U34: =SUM(I34:T34) -> 2250 | W34: =+$G34*I34 -> 0 | X34: =+$G34*J34 -> 0 | Y34: =+$G34*K34 -> 0 | Z34: =+$G34*L34 -> 12675 | AA34: =+$G34*M34 -> 0 | AB34: =+$G34*N34 -> 0 | AC34: =+$G34*O34 -> 12675 | AD34: =+$G34*P34 -> 0 | ... AH34: =+$G34*T34 -> 0 | AI34: =SUM(W34:AH34) -> 38025
A35: 337 | B35: CERVECERIA CUAUHTEMOC MOCTEZUMA SA DE CV | C35: CON-0343 | D35: TERMAMYL SC DS CONTENEDOR 1200 KG | E35: CERVEZA | F35: ROGELIO CURIEL | G35: 12.98 | H35: PRESUPUESTO | J35: 1200 | R35: 1200 | U35: =SUM(I35:T35) -> 2400 | W35: =+$G35*I35 -> 0 | X35: =+$G35*J35 -> 15576 | Y35: =+$G35*K35 -> 0 | Z35: =+$G35*L35 -> 0 | AA35: =+$G35*M35 -> 0 | AB35: =+$G35*N35 -> 0 | AC35: =+$G35*O35 -> 0 | AD35: =+$G35*P35 -> 0 | ... AH35: =+$G35*T35 -> 0 | AI35: =SUM(W35:AH35) -> 31152 | AJ35: =SUM(AI32:AI35) -> 571887
A36: 342 | B36: RED STRIPE | C36: MP-0184 | D36: MATUREX PRO | E36: CERVEZA | F36: ROGELIO CURIEL | G36: 81.36 | H36: PRESUPUESTO | K36: 200 | Q36: 250 | U36: =SUM(I36:T36) -> 450 | W36: =+$G36*I36 -> 0 | X36: =+$G36*J36 -> 0 | Y36: =+$G36*K36 -> 16272 | Z36: =+$G36*L36 -> 0 | AA36: =+$G36*M36 -> 0 | AB36: =+$G36*N36 -> 0 | AC36: =+$G36*O36 -> 0 | AD36: =+$G36*P36 -> 0 | ... AH36: =+$G36*T36 -> 0 | AI36: =SUM(W36:AH36) -> 36612 | AJ36: =AI36 -> 36612
A37: 393 | B37: CERVECERIA CUAUHTEMOC MOCTEZUMA SA DE CV | C37: MP-0268 | D37: ULTRAFLO PRIME | E37: CERVEZA | F37: ROGELIO CURIEL | G37: 28.78 | H37: PRESUPUESTO | I37: 1100 | J37: 1100 | K37: 1100 | L37: 1100 | M37: 1100 | N37: 1100 | O37: 1100 | P37: 1100 | Q37: 1100 | R37: 1100 | S37: 1100 | T37: 1100 | U37: =SUM(I37:T37) -> 13200 | W37: =+$G37*I37 -> 31658 | X37: =+$G37*J37 -> 31658 | Y37: =+$G37*K37 -> 31658 | Z37: =+$G37*L37 -> 31658 | AA37: =+$G37*M37 -> 31658 | AB37: =+$G37*N37 -> 31658 | AC37: =+$G37*O37 -> 31658 | AD37: =+$G37*P37 -> 31658 | ... AH37: =+$G37*T37 -> 31658 | AI37: =SUM(W37:AH37) -> 379896 | AJ37: =AI37 -> 379896
A38: 436 | B38: CERVECERIA PANAMA, S.A. | C38: MP-0184 | D38: MATUREX PRO | E38: CERVEZA | F38: ROGELIO CURIEL | G38: 81.36 | H38: PRESUPUESTO | I38: 40 | J38: 40 | K38: 40 | L38: 40 | M38: 40 | N38: 40 | O38: 40 | P38: 40 | Q38: 40 | R38: 40 | S38: 40 | T38: 40 | U38: =SUM(I38:T38) -> 480 | W38: =+$G38*I38 -> 3254.4 | X38: =+$G38*J38 -> 3254.4 | Y38: =+$G38*K38 -> 3254.4 | Z38: =+$G38*L38 -> 3254.4 | AA38: =+$G38*M38 -> 3254.4 | AB38: =+$G38*N38 -> 3254.4 | AC38: =+$G38*O38 -> 3254.4 | AD38: =+$G38*P38 -> 3254.4 | ... AH38: =+$G38*T38 -> 3254.4 | AI38: =SUM(W38:AH38) -> 39052.8 | AJ38: =AI38 -> 39052.8
A39: 500 | B39: HEINEKEN PERU SAC | C39: POR-0352 | D39: ULTRAFLO MAX | E39: CERVEZA | F39: ROGELIO CURIEL | G39: 26.54 | H39: PRESUPUESTO | K39: 50 | R39: 50 | U39: =SUM(I39:T39) -> 100 | W39: =+$G39*I39 -> 0 | X39: =+$G39*J39 -> 0 | Y39: =+$G39*K39 -> 1327 | Z39: =+$G39*L39 -> 0 | AA39: =+$G39*M39 -> 0 | AB39: =+$G39*N39 -> 0 | AC39: =+$G39*O39 -> 0 | AD39: =+$G39*P39 -> 0 | ... AH39: =+$G39*T39 -> 0 | AI39: =SUM(W39:AH39) -> 2654
A40: 500 | B40: HEINEKEN PERU SAC | C40: =IF(ISERROR(VLOOKUP(D40,[2]PRODUCTOS!$B$2:$J$800,9,0)),"",(VLOOKUP(D40,[2]PRODUCTOS!$B$2:$J$800,9,0))) -> MP-0066 | D40: ATTENUZYME PRO | E40: CERVEZA | F40: ROGELIO CURIEL | G40: 13.6 | H40: PRESUPUESTO | I40: 50 | M40: 50 | Q40: 50 | T40: 50 | U40: =SUM(I40:T40) -> 200 | W40: =+$G40*I40 -> 680 | X40: =+$G40*J40 -> 0 | Y40: =+$G40*K40 -> 0 | Z40: =+$G40*L40 -> 0 | AA40: =+$G40*M40 -> 680 | AB40: =+$G40*N40 -> 0 | AC40: =+$G40*O40 -> 0 | AD40: =+$G40*P40 -> 0 | ... AH40: =+$G40*T40 -> 680 | AI40: =SUM(W40:AH40) -> 2720
A41: 500 | B41: HEINEKEN PERU SAC | C41: MP-0246 | D41: TERMAMYL SC 4X PORRON 25 KG | E41: CERVEZA | F41: ROGELIO CURIEL | G41: 12.73 | H41: PRESUPUESTO | K41: 25 | R41: 25 | U41: =SUM(I41:T41) -> 50 | W41: =+$G41*I41 -> 0 | X41: =+$G41*J41 -> 0 | Y41: =+$G41*K41 -> 318.25 | Z41: =+$G41*L41 -> 0 | AA41: =+$G41*M41 -> 0 | AB41: =+$G41*N41 -> 0 | AC41: =+$G41*O41 -> 0 | AD41: =+$G41*P41 -> 0 | ... AH41: =+$G41*T41 -> 0 | AI41: =SUM(W41:AH41) -> 636.5 | AJ41: =SUM(AI39:AI41) -> 6010.5 | AK41: =SUM(AI4:AI41) -> 4081892.4
A42: 392 | B42: CI CERVEZA GmbH. | C42: CON-0066 | D42: ATTENUZYME PRO | E42: CERVEZA | F42: ROGELIO CURIEL | G42: 18.32 | H42: PRESUPUESTO | J42: 8800 | K42: 16500 | M42: 16500 | N42: 13200 | P42: 15400 | R42: 7700 | S42: 13200 | U42: =SUM(I42:T42) -> 91300 | W42: =+$G42*I42 -> 0 | X42: =+$G42*J42 -> 161216 | Y42: =+$G42*K42 -> 302280 | Z42: =+$G42*L42 -> 0 | AA42: =+$G42*M42 -> 302280 | AB42: =+$G42*N42 -> 241824 | AC42: =+$G42*O42 -> 0 | AD42: =+$G42*P42 -> 282128 | ... AH42: =+$G42*T42 -> 0 | AI42: =SUM(W42:AH42) -> 1672616
...

Sheet EDGAR 2026
B4: PRESUPUESTO EDGAR MUÑOZ 2026 | I4: KILOGRAMOS | W4: USD
A5: CLAVE CLIENTE | B5: NOMBRE DEL CLIENTE | C5: CLAVE DEL PRODUCTO SKU | D5: PRODUCTO | E5: AREA | F5: VENDEDOR | G5: PRECIO UNITARIO EN DÓLARES | H5: TIPO | I5: ENERO | J5: FEBRERO | K5: MARZO | L5: ABRIL | M5: MAYO | N5: JUNIO | O5: JULIO | P5: AGOSTO | Q5: SEPTIEMBRE | R5: OCTUBRE | S5: NOVIEMBRE | T5: DICIEMBRE | U5: TOTAL | W5: ENERO | X5: FEBRERO | Y5: MARZO | Z5: ABRIL | AA5: MAYO | AB5: JUNIO | AC5: JULIO | AD5: AGOSTO | AE5: SEPTIEMBRE | AF5: OCTUBRE | AG5: NOVIEMBRE | AH5: DICIEMBRE | AI5: TOTAL USD
A6: 14 | B6: DISTRIBUIDORA TEXTIL ARTTEX | C6: 163 | D6: CELLUSOFT CR | E6: TEXTIL | F6: EDGAR MUÑOZ | G6: 5.68 | H6: PRESUPUESTO | I6: 0 | J6: 200 | K6: 0 | L6: 200 | M6: 0 | N6: 200 | O6: 0 | P6: 200 | Q6: 0 | R6: 200 | S6: 0 | T6: 200 | U6: =SUM(I6:T6) -> 1200 | W6: =I6*G6 -> 0 | X6: =J6*G6 -> 1136 | Y6: =K6*G6 -> 0 | Z6: =L6*G6 -> 1136 | AA6: =M6*G6 -> 0 | AB6: =N6*G6 -> 1136 | AC6: =O6*G6 -> 0 | AD6: =P6*G6 -> 1136 | AE6: =Q6*G6 -> 0 | AF6: =R6*G6 -> 1136 | AG6: =S6*G6 -> 0 | AH6: =T6*G6 -> 1136 | AI6: =SUM(W6:AH6) -> 6816
