Workbook

Sheet Resultados
A4: Check list de PPR´s
A6: RESULTADOS DEL MES DE ______________
A8: Prerrequisito | E8: Documentación | F8: Piso | G8: Global
A9: 1. BPM´s | E9: ='1.BPM´s '!I13 -> 0 | F9: ='1.BPM´s '!I27 -> 0 | G9: ='1.BPM´s '!I29 -> 0
A10: 2. Limpieza | E10: ='2.Limpieza'!I13 -> 0 | F10: ='2.Limpieza'!I22 -> 0 | G10: ='2.Limpieza'!I24 -> 0
A11: 3. Químicos | E11: ='3. Químicos'!I13 -> 0 | F11: ='3. Químicos'!I22 -> 0 | G11: ='3. Químicos'!I24 -> 0
A12: 4. Control de Plagas | E12: ='4.Plagas'!I19 -> 0 | F12: ='4.Plagas'!I29 -> 0 | G12: ='4.Plagas'!I31 -> 0
A13: 5. Microbiología | E13: ='5.Microbiología'!I15 -> 0 | F13: ='5.Microbiología'!I26 -> 0 | G13: ='5.Microbiología'!I28 -> 0
A14: 6. Mantenimiento | E14: ='6.MTTO'!I13 -> 0 | F14: ='6.MTTO'!I21 -> 0 | G14: ='6.MTTO'!I23 -> 0
A15: 7. Vidrio y Plástico | E15: ='7.Vidrio y plástico'!I13 -> 0 | F15: ='7.Vidrio y plástico'!I20 -> 0 | G15: ='7.Vidrio y plástico'!I22 -> 0
A16: 8. Material Extraño | E16: ='8. Materia extraña'!I13 -> 0 | F16: ='8. Materia extraña'!I19 -> 0 | G16: ='8. Materia extraña'!I21 -> 0
A17: 9. Alérgenos | E17: ='9.Alérgenos'!I16 -> 0 | F17: ='9.Alérgenos'!I26 -> 0 | G17: ='9.Alérgenos'!I28 -> 0
A18: 10. Recuperación y trazabilidad | E18: ='10. Recuperación y trazabilidad'!I13 -> 0 | F18: ='10. Recuperación y trazabilidad'!I19 -> 0 | G18: ='10. Recuperación y trazabilidad'!I21 -> 0
A19: 11. Calibración | E19: ='11.Calibración'!I15 -> 0 | F19: ='11.Calibración'!I22 -> 0 | G19: ='11.Calibración'!I24 -> 0
A20: 12. Almacenamiento | E20: ='12. Almacenamiento.'!I14 -> 0 | F20: ='12. Almacenamiento.'!I26 -> 0 | G20: ='12. Almacenamiento.'!I28 -> 0
A21: 13. Compras | E21: ='13. Compras'!I14 -> 0 | F21: ='13. Compras'!I20 -> 0 | G21: ='13. Compras'!I22 -> 0
A22: 14. Defensa de Alimentos | E22: ='14. Defensa'!I14 -> 0 | F22: ='14. Defensa'!I22 -> 0 | G22: ='14. Defensa'!I24 -> 0
A23: 15. Gestión de Residuos | E23: ='15. Residuos'!I12 -> 0 | F23: ='15. Residuos'!I22 -> 0 | G23: ='15. Residuos'!I24 -> 0
A26: Documentación | E26: =AVERAGE(E9:E23) -> 0
A27: Piso | E27: =AVERAGE(F9:F23) -> 0
A28: Global | E28: =AVERAGE(G9:G23) -> 0

Sheet Global
A4: Check list de PPR´s

Sheet Documentación
A4: Check list de PPR´s

Sheet Piso
A4: Check list de PPR´s

Sheet Doc+Piso
A4: Check list de PPR´s

Sheet 1.BPM´s 
A4: Check list de PPR´s
A5: 1. Buenas Prácticas de Manufactura
A8: Verificación documental | F8: Cumple | G8: No Cumple | H8: % Optimo | I8: % Obtenido | J8: Comentarios
A9: 1. La capacitación de BPM´S tiene una frecuencia anual y contempla al 100% del personal y se cumple. | H9: 0.25 | I9: =IF(F9>0,H9,0%) -> 0
A10: 2. Existen ayudas visuales del método de lavado de manos para consulta del personal. (producción, sanitarios, comedor etc.) | H10: 0.25 | I10: =IF(F10>0,H10,0%) -> 0
A11: 3. Está documentado la realización de los análisis clínicos necesarios a los empleados, y está incluido que hacer en caso de que estén fuera de parámetros aceptables. | H11: 0.25 | I11: =IF(F11>0,H11,0%) -> 0
A12: 4. Existen registros de los resultados de los análisis clínicos marcados en las fechas estipuladas. Se le da seguimiento documentado al personal que se encuentra bajo tratamiento médico. | H12: 0.25 | I12: =IF(F12>0,H12,0%) -> 0
G13: Total | H13: 1 | I13: =SUM(I9:I12) -> 0
A15: Verificación en piso | F15: Cumple | G15: No Cumple | H15: % Optimo | I15: % Obtenido | J15: Comentarios
A16: 1. El personal conoce las BPM´S, desde operarios hasta personal administrativo. Entreviste a 4 personas. | H16: =$H$27/11 -> 0.090909091 | I16: 0
A17: 2.- El personal utiliza uniforme limpio, completo y en condiciones apropiadas de uso de acuerdo a su área de trabajo. | H17: =$H$27/11 -> 0.090909091 | I17: =IF(F17>0,H17,0%) -> 0
A18: 3.- Se observa el personal con barba afeitada, bigote recortado, el cabello corto, uñas recortadas y se evita el uso de uñas postizas, barniz en las uñas, uñas sucias, el uso de maquillaje, perfumes, medicamentos, lociones para piel y de pestañas postizas. | H18: =$H$27/11 -> 0.090909091 | I18: 0
A19: 4.- Se observa que no hay evidencia de consumo de bebidas, goma de mascar, alimentos, tabaco, alcohol etc, además muestra buenos hábitos al no escupir en ningún área, o toser sobre envase o producto. | H19: =$H$27/11 -> 0.090909091 | I19: =IF(F19>0,H19,0%) -> 0
A20: 5.- Se prohíbe el uso de joyería incluyendo relojes, pulseras, cadenas, anillos, collares, piercing, llaveros, y ligas, broches o pasadores para el cabello, llaveros, o cualquier otro objeto suelto o que potencialmente pueda aflojarse y contaminar productos, materias primas o insumos. | H20: =$H$27/11 -> 0.090909091 | I20: =IF(F20>0,H20,0%) -> 0
A21: 6.- El personal conoce el procedimiento de lavado de manos, así como la frecuencia. | H21: =$H$27/11 -> 0.090909091 | I21: =IF(F21>0,H21,0%) -> 0
A22: 7.- Verifique que las estaciones de lavado de manos funcionen correctamente, cuentan con agua corriente, jabón bactericida, sanitizante, toallas de papel y cesto para basura | H22: =$H$27/11 -> 0.090909091 | I22: =IF(F22>0,H22,0%) -> 0
A23: 8.- El personal tiene conocimiento sobre que hacer en caso de presencia de algún síntoma de enfermedad infecto-contagiosa | H23: =$H$27/11 -> 0.090909091 | I23: =IF(F23>0,H23,0%) -> 0
A24: 9.- Los baños están limpios, funcionan correctamente y se mantienen cerrados. | H24: =$H$27/11 -> 0.090909091 | I24: =IF(F24>0,H24,0%) -> 0
A25: 10.-Los casilleros se encuentran limpios, libres de basura, ropa o equipos contaminados, herramienta, medicamentos, químicos o alimentos. | H25: =$H$27/11 -> 0.090909091 | I25: =IF(F25>0,H25,0%) -> 0
A26: 11.- Las áreas se mantienen limpias, ordenadas, libres de ropa, objetos personales, o astillas de madera. | H26: =$H$27/11 -> 0.090909091 | I26: =IF(F26>0,H26,0%) -> 0
G27: Total | H27: 1 | I27: =SUM(I16:I26) -> 0
F29: % de cumplimiento total | I29: =AVERAGE(I13,I27) -> 0
A31: Marcar con una X el Área Evaluada
A32: 1 | B32: Almacén | G32: Fecha de verificación:
A33: 2 | B33: Aseguramiento de calidad
A34: 3 | B34: Control de calidad | G34: Nombre y Firma del Evaluador
A35: 4 | B35: Desarrollos
A36: 5 | B36: Mantenimiento | G36: Nombre y Firma del Responsables de área
A37: 6 | B37: Producción

Sheet 2.Limpieza
A4: Check list de PPR´s
A5: 2. Limpieza y desinfección
A8: Verificación documental | F8: Cumple | G8: No Cumple | H8: % Optimo | I8: % Obtenido | J8: Comentarios
A9: 1. Se cuenta con planes maestros de limpieza de todas las áreas (internas y externas), incluyendo equipos, lámparas, techos etc. Y cada actividad es registrada en los formatos correspondientes. | H9: 0.25 | I9: =IF(F9>0,H9,0%) -> 0
A10: 2. Se cuenta con procedimientos o instructivos para la realización de la limpieza de cada actividad . | H10: 0.25 | I10: =IF(F10>0,H10,0%) -> 0
A11: 3. Los saneamientos de equipos cuentan con liberaciones que detallan el cumplimiento de los requerimientos tales como: ATP, hisopado de alérgenos. | H11: 0.25 | I11: =IF(F11>0,H11,0%) -> 0
A12: 4. Los procedimientos de limpieza y saneamiento incluyen actividades a realizar en caso de que no se cumplan los requerimientos. | H12: 0.25 | I12: =IF(F12>0,H12,0%) -> 0
G13: Total | H13: 1 | I13: =SUM(I9:I12) -> 0
A15: Verificación en piso | F15: Cumple | G15: No Cumple | H15: % Optimo | I15: % Obtenido | J15: Comentarios
A16: 1. Las áreas se encuentran libres de suciedad y libres de hongos | H16: 0.1667 | I16: 0
A17: 2. Se respeta el código de colores en los utensilios de limpieza. | H17: 0.1667 | I17: =IF(F17>0,H17,0%) -> 0
A18: 3. Las frecuencias establecidas de limpieza de instalaciones se respetan de acuerdo al programa establecido. | H18: 0.1667 | I18: 0
A19: 4. Únicamente se utilizan en planta agentes de limpieza y saneamiento autorizados para su uso en plantas de alimentos (solo aplica producción). | H19: 0.1667 | I19: =IF(F19>0,H19,0%) -> 0
A20: 5. Los utensilios para limpieza y sus materiales no representan un riesgo de contaminación hacia el producto y proceso. Solo aplica a producción. | H20: 0.1667 | I20: =IF(F20>0,H20,0%) -> 0
A21: 6. Los materiales de limpieza (cepillos, escobas, paños, etc.) se almacenan limpios después de su uso, y está asignada un área y ordenados. | H21: 0.1667 | I21: =IF(F21>0,H21,0%) -> 0
G22: Total | H22: 1 | I22: =SUM(I16:I21) -> 0
F24: % de cumplimiento total | I24: =AVERAGE(I13,I22) -> 0
A26: Marcar con una X el Área Evaluada
A27: 1 | B27: Almacén | G27: Fecha de verificación:
A28: 2 | B28: Aseguramiento de calidad
A29: 3 | B29: Control de calidad | G29: Nombre y Firma del Evaluador
A30: 4 | B30: Desarrollos
A31: 5 | B31: Mantenimiento | G31: Nombre y Firma del Responsables de área
A32: 6 | B32: Producción

Sheet 3. Químicos
A4: Check list de PPR´s
A5: 3. Control de químicos
A8: Verificación documental | F8: Cumple | G8: No Cumple | H8: % Optimo | I8: % Obtenido | J8: Comentarios
A9: 1. Se tiene un listado actualizado de todos los químicos permitidos en planta, que considera químicos de Limpieza, mantenimiento, laboratorio, manejo de plagas etc. | H9: 0.25 | I9: =IF(F9>0,H9,0%) -> 0
A10: 2. Se cuenta con todas las fichas técnicas y hojas de seguridad en las áreas especificas de uso o almacenamiento. | H10: 0.25 | I10: =IF(F10>0,H10,0%) -> 0
A11: 3. El personal de planta cuenta con los registros de capacitación sobre el manejo y almacenamiento de químicos. | H11: 0.25 | I11: =IF(F11>0,H11,0%) -> 0
A12: 4. Se cuenta con los documentos (fichas técnicas, cartas garantía, registros de aprobación, etc ) de los químicos para su uso en plantas de alimentos y/ o grado alimentario, por ejemplo lubricantes etc. | H12: 0.25 | I12: =IF(F12>0,H12,0%) -> 0
G13: Total | H13: 1 | I13: =SUM(I9:I12) -> 0
A15: Verificación en piso | F15: Cumple | G15: No Cumple | H15: % Optimo | I15: % Obtenido | J15: Comentarios
A16: 1. El personal tiene un manejo adecuado de los químicos, de acuerdo a los procedimientos y etiquetado | H16: 0.1667 | I16: 0
A17: 2. Se lleva un inventario al día, por medio del uso de la bitacora CCBT06 de las diferentes áreas (producción, desarrollos,calidad, comedor), así como de su entrega a las diferentes áreas (cuando aplique). | H17: 0.1667 | I17: =IF(F17>0,H17,0%) -> 0
A18: 3. Los químicos grado alimentario y sus utensilios están separados de los demás químicos, y se manejan de tal forma que se evite una contaminación de los mismos. | H18: 0.1667 | I18: 0
A19: 4. Los químicos en planta y almacén se encuentran bajo llave cuando no se están utilizando (si no hay personal supervisándolos). | H19: 0.1667 | I19: =IF(F19>0,H19,0%) -> 0
A20: 5. El personal encargado de la manipulación de los químicos sabe que hacer en caso de una fuga o derrame (consulta hojas de seguridad / ayuda a controlar derrames / conoce la ruta de evacuación / sabe dónde se almacenan los residuos peligrosos). Entreviste a los empleados sobre la manera correcta de almacenar y manejar el producto químico. | H20: 0.1667 | I20: =IF(F20>0,H20,0%) -> 0
A21: 6. Durante el recorrido, se observó que todos los químicos se encontraban identificados de acuerdo a lo marcado en el procedimiento. | H21: 0.1667 | I21: =IF(F21>0,H21,0%) -> 0
G22: Total | H22: 1 | I22: =SUM(I16:I21) -> 0
F24: % de cumplimiento total | I24: =AVERAGE(I13,I22) -> 0
A26: Marcar con una X el Área Evaluada
A27: 1 | B27: Almacén | G27: Fecha de verificación:
A28: 2 | B28: Aseguramiento de calidad
A29: 3 | B29: Control de calidad | G29: Nombre y Firma del Evaluador
A30: 4 | B30: Desarrollos
A31: 5 | B31: Mantenimiento | G31: Nombre y Firma del Responsables de área
A32: 6 | B32: Producción

Sheet 1.BPM´s (almacenes)
B2: Listado de Cumplimiento de Prerrequisitos
B3: EMBOTELLADORA AGUASCALIENTES S.A. DE C.V
B4: CEPRO/CEDIS LAS TROJES
B5: EVALUACIÓN DE BUENAS PRÁCTICAS DE MANUFACTURA (ALMACENES)
A7: Verificación de documentación | E7: Cumple | F7: No Cumple | G7: % Optimo | H7: % Obtenido | I7: Observaciones
A8: 1. Se cuenta con un manual de BHM's. | G8: =$G$18/10 -> 0.04 | H8: =IF(E8>0,G8,0%) -> 0
A9: 2. El manual de BHM's es conocido por todo el personal de planta, así como personal externo que ingresa a realizar actividades a áreas de producción. | G9: =$G$18/10 -> 0.04 | H9: =IF(E9>0,G9,0%) -> 0
A10: 3. El manual de BHM's abarca todas las áreas de la planta. | G10: =$G$18/10 -> 0.04 | H10: =IF(E10>0,G10,0%) -> 0
A11: 4. El manual cumple con la ley que rige al país de origen y de destino. | G11: =$G$18/10 -> 0.04 | H11: =IF(E11>0,G11,0%) -> 0
A12: 5. La planta tiene un sistema de evaluación de las BHM´S en piso, y las evaluaciones se hacen con la frecuencia determinada y son actualizadas. | G12: =$G$18/10 -> 0.04 | H12: =IF(E12>0,G12,0%) -> 0
A13: 6. Existen registros de una inducción para el personal de nuevo ingreso, incluyendo contratistas y proveedores. | G13: =$G$18/10 -> 0.04 | H13: =IF(E13>0,G13,0%) -> 0
A14: 7. La capacitación de BHM´S tiene una frecuencia anual y contempla al 100% del personal y se cumple. | G14: =$G$18/10 -> 0.04 | H14: =IF(E14>0,G14,0%) -> 0
A15: 8. Existe una metodología documentada para el lavado y saneamiento de manos para los trabajadores. | G15: =$G$18/10 -> 0.04 | H15: =IF(E15>0,G15,0%) -> 0
A16: 9. Se cuenta con un requerimiento específico sobre el uso de cofia y cubre boca cuando los ingredientes, materiales y producto se encuentran expuestos. | G16: =$G$18/10 -> 0.04 | H16: =IF(E16>0,G16,0%) -> 0
A17: 10. El programa contempla la segregación del personal con síntomas de enfermedad o cortaduras y/o lesiones expuestas, y se excluyen de trabajos que involucren el manejo de alimentos. | G17: =$G$18/10 -> 0.04 | H17: =IF(E17>0,G17,0%) -> 0
F18: Total | G18: 0.4 | H18: =SUM(H8:H17) -> 0
A20: Verificación en piso | E20: Cumple | F20: No Cumple | G20: % Optimo | H20: % Obtenido | I20: Observaciones
A21: 1. El personal conoce las BPM´S, desde operarios hasta personal administrativo. Entreviste a 4 personas. | G21: =$G$33/12 -> 0.05 | H21: =IF(E21>0,G21,0%) -> 0
A22: 2.- El personal utiliza uniforme limpio, completo y en condiciones apropiadas de uso de acuerdo a su área (camisa, pantalón y calzado). | G22: =$G$33/12 -> 0.05 | H22: =IF(E22>0,G22,0%) -> 0
A23: 3.- Los empleados, contratistas y visitantes son responsables del buen uso, la limpieza y la integridad de su equipo de protección personal. | G23: =$G$33/12 -> 0.05 | H23: =IF(E23>0,G23,0%) -> 0
A24: 4.- Se observa que el personal lava su uniforme diariamente | G24: =$G$33/12 -> 0.05 | H24: =IF(E24>0,G24,0%) -> 0
A25: 5.- Se observa el personal con barba afeitada, bigote recortado, el cabello corto. | G25: =$G$33/12 -> 0.05 | H25: =IF(E25>0,G25,0%) -> 0
A26: 6.- Se observa que no hay evidencia de consumo de bebidas, goma de mascar, alimentos, tabaco alcohol y drogas ilegales. | G26: =$G$33/12 -> 0.05 | H26: =IF(E26>0,G26,0%) -> 0
A27: 7.- El personal debe de evitar los siguiente: el uso de botellas de los productos que elaboramos como recipiente para cualquier otra sustancia, Ingresar químicos no autorizados, medicamentos o cualquier material no autorizado tales como, recipientes ó articulos de vidrio, plástico quebradizo y cerámica, ingresar animales. | G27: =$G$33/12 -> 0.05 | H27: =IF(E27>0,G27,0%) -> 0
A28: 8.- El personal interno y externo ha participado en cursos de capacitación relacionados con buenas prácticas de manufactura y demuestra tener conocimiento. (Revisar registros) | G28: =$G$33/12 -> 0.05 | H28: =IF(E28>0,G28,0%) -> 0
A29: 9.- Se cuenta con ayudas visuales sobre las BPM´S en la planta como ayuda para el personal. | G29: =$G$33/12 -> 0.05 | H29: =IF(E29>0,G29,0%) -> 0
A30: 10.- En el área de almacenamiento y áreas productivas verifique el uso del Formato Lista de Verificación de Buenas Prácticas de Manufactura | G30: =$G$33/12 -> 0.05 | H30: =IF(E30>0,G30,0%) -> 0
A31: 11.- El área se encuentra limpia, libre de ropa u objetos personales. | G31: =$G$33/12 -> 0.05 | H31: =IF(E31>0,G31,0%) -> 0
A32: 12.- El personal evita tomar agua en envases de refresco. | G32: =$G$33/12 -> 0.05 | H32: =IF(E32>0,G32,0%) -> 0
F33: Total | G33: 0.6 | H33: =SUM(H21:H32) -> 0
F35: Cumplimiento Total | H35: =SUM(H33+H18) -> 0
A37: Fecha: | I37: Marcar con una X el Área Evaluada
I38: 1 | J38: Oficinas Generales
A39: Nombre y Firma del Evaluador | I39: 2 | J39: Servicios Generales
I40: 3 | J40: APE
I41: 4 | J41: Producción | K41: X
A42: Nombre y Firma del Personal Evaluado | I42: 5 | J42: PTAR
I43: 6 | J43: Transporte
I44: 7 | J44: Patios y Estacionamientos
J46: INA-E-F4-700.01.04

Sheet 1.BPM´s (producción)
B2: Listado de Cumplimiento de Prerrequisitos
B3: EMBOTELLADORA AGUASCALIENTES S.A. DE C.V
B4: CEPRO/CEDIS LAS TROJES
B5: EVALUACIÓN DE BUENAS PRÁCTICAS DE MANUFACTURA (PRODUCCIÓN)
A7: Verificación de documentación | E7: Cumple | F7: No Cumple | G7: % Optimo | H7: % Obtenido | I7: Observaciones
A8: 1. Se cuenta con un manual de BHM's. | G8: =$G$18/10 -> 0.04 | H8: =IF(E8>0,G8,0%) -> 0
A9: 2. El manual de BHM's es conocido por todo el personal de planta, así como personal externo que ingresa a realizar actividades a áreas de producción. | G9: =$G$18/10 -> 0.04 | H9: =IF(E9>0,G9,0%) -> 0
A10: 3. El manual de BHM's abarca todas las áreas de la planta. | G10: =$G$18/10 -> 0.04 | H10: =IF(E10>0,G10,0%) -> 0
A11: 4. El manual cumple con la ley que rige al país de origen y de destino. | G11: =$G$18/10 -> 0.04 | H11: =IF(E11>0,G11,0%) -> 0
A12: 5. La planta tiene un sistema de evaluación de las BHM´S en piso, y las evaluaciones se hacen con la frecuencia determinada y son actualizadas. | G12: =$G$18/10 -> 0.04 | H12: =IF(E12>0,G12,0%) -> 0
A13: 6. Existen registros de una inducción para el personal de nuevo ingreso, incluyendo contratistas y proveedores. | G13: =$G$18/10 -> 0.04 | H13: =IF(E13>0,G13,0%) -> 0
A14: 7. La capacitación de BHM´S tiene una frecuencia anual y contempla al 100% del personal y se cumple. | G14: =$G$18/10 -> 0.04 | H14: =IF(E14>0,G14,0%) -> 0
A15: 8. Existe una metodología documentada para el lavado y saneamiento de manos para los trabajadores. | G15: =$G$18/10 -> 0.04 | H15: =IF(E15>0,G15,0%) -> 0
A16: 9. Se cuenta con un requerimiento específico sobre el uso de cofia y cubre boca cuando los ingredientes, materiales y producto se encuentran expuestos. | G16: =$G$18/10 -> 0.04 | H16: =IF(E16>0,G16,0%) -> 0
A17: 10. El programa contempla la segregación del personal con síntomas de enfermedad o cortaduras y/o lesiones expuestas, y se excluyen de trabajos que involucren el manejo de alimentos. | G17: =$G$18/10 -> 0.04 | H17: =IF(E17>0,G17,0%) -> 0
F18: Total | G18: 0.4 | H18: =SUM(H8:H17) -> 0
A20: Verificación en piso | E20: Cumple | F20: No Cumple | G20: % Optimo | H20: % Obtenido | I20: Observaciones
A21: 1. El personal conoce las BPM´S, desde operarios hasta personal administrativo. Entreviste a 4 personas. | G21: =$G$43/22 -> 0.027272727 | H21: =IF(E21>0,G21,0%) -> 0
A22: 2.- El personal utiliza uniforme limpio, completo y en condiciones apropiadas de uso de acuerdo a su área (camisa, pantalón y calzado). | G22: =$G$43/22 -> 0.027272727 | H22: =IF(E22>0,G22,0%) -> 0
A23: 3.- Los empleados, contratistas y visitantes son responsables del buen uso, la limpieza y la integridad de su equipo de protección personal. | G23: =$G$43/22 -> 0.027272727 | H23: =IF(E23>0,G23,0%) -> 0
A24: 4.- Se observa que el personal lava su uniforme diariamente | G24: =$G$43/22 -> 0.027272727 | H24: =IF(E24>0,G24,0%) -> 0
A25: 5.- Se observa el personal con barba afeitada, bigote recortado, el cabello corto, traer uñas recortadas y se evita el uso de uñas postizas, barniz en las uñas, uñas sucias, el uso de maquillaje, perfumes, medicamentos, lociones para piel, cremas, pomadas y de pestañas postizas. | G25: =$G$43/22 -> 0.027272727 | H25: =IF(E25>0,G25,0%) -> 0
A26: 6.- Se observa que no hay evidencia de consumo de bebidas, goma de mascar, alimentos, tabaco alcohol y drogas ilegales, además muestra buenos hábitos al no escupir en ningún área, o toser sobre envase o producto. | G26: =$G$43/22 -> 0.027272727 | H26: =IF(E26>0,G26,0%) -> 0
A27: 7.- El personal debe de evitar los siguiente: el uso de botellas de los productos que elaboramos como recipiente para cualquier otra sustancia, Ingresar químicos no autorizados, medicamentos o cualquier material no autorizado tales como, recipientes ó articulos de vidrio, plástico quebradizo y cerámica, ingresar animales. | G27: =$G$43/22 -> 0.027272727 | H27: =IF(E27>0,G27,0%) -> 0
A28: 8.- El personal interno y externo ha participado en cursos de capacitación relacionados con buenas prácticas de manufactura y demuestra tener conocimiento. (Revisar registros) | G28: =$G$43/22 -> 0.027272727 | H28: =IF(E28>0,G28,0%) -> 0
A29: 9.- Se cuenta con ayudas visuales sobre las BPM´S en la planta como ayuda para el personal. | G29: =$G$43/22 -> 0.027272727 | H29: =IF(E29>0,G29,0%) -> 0
A30: 10.- En el área de almacenamiento y áreas productivas verifique el uso del Formato Lista de Verificación de Buenas Prácticas de Manufactura | G30: =$G$43/22 -> 0.027272727 | H30: =IF(E30>0,G30,0%) -> 0
A31: 11.- Los empleados Contratistas y visitantes deben portar casco, cofia, cubre bocas y de acuerdo a la necesidades de las actividades a realizar o áreas a visitar deben estar dotados de mandil, lentes de seguridad, protección auditiva, guantes, faja, respiradores, calzado de seguridad cerrado y no absorbente. | G31: =$G$43/22 -> 0.027272727 | H31: =IF(E31>0,G31,0%) -> 0
A32: 12.- Se prohíbe el uso de joyería incluyendo relojes, pulseras, cadenas, anillos, collares, piercing, llaveros, y ligas, broches o pasadores para el cabello, llaveros, o cualquier otro objeto suelto o que potencialmente pueda aflojarse y contaminar productos, materias primas o insumos. | G32: =$G$43/22 -> 0.027272727 | H32: =IF(E32>0,G32,0%) -> 0
... A42: 22.- Las áreas se mantienen limpias, ordenadas, libres de ropa, objetos personales, madera (excepto tarimas para producto terminado) | G42: =$G$43/22 -> 0.027272727 | H42: =IF(E42>0,G42,0%) -> 0
F43: Total | G43: 0.6 | H43: =SUM(H21:H42) -> 0
F45: Cumplimiento Total | H45: =SUM(H43+H18) -> 0
A47: Fecha: | I47: Marcar con una X el Área Evaluada
I48: 1 | J48: Oficinas Generales
A49: Nombre y Firma del Evaluador | I49: 2 | J49: Servicios Generales
I50: 3 | J50: APE
I51: 4 | J51: Producción | K51: X
A52: Nombre y Firma del Personal Evaluado | I52: 5 | J52: PTAR
I53: 6 | J53: Transporte
I54: 7 | J54: Patios y Estacionamientos
...

Sheet 4.Plagas
A4: Check list de PPR´s
A5: 4. Control de plagas
A8: Verificación documental | F8: Cumple | G8: No Cumple | H8: % Optimo | I8: % Obtenido | J8: Comentarios
A9: 1. Se cuenta con un seguro de responsabilidad civil vigente por parte de la compañía externa. | H9: 0.1 | I9: =IF(F9>0,H9,0%) -> 0
A10: 2. Se tiene un listado de los plaguicidas autorizados para su uso dentro de la planta, copias de etiquetas, registros de Cicloplafest y hojas de seguridad de cada uno de los plaguicidas que serán utilizados en las instalaciones de la planta, así como la rotación de los mismos. | H10: 0.1 | I10: =IF(F10>0,H10,0%) -> 0
A11: 3. La compañía de plagas cuenta con procedimientos basados en las plagas objetivo, para todas las actividades que se realizan dentro y en los alrededores de la planta. | H11: 0.1 | I11: =IF(F11>0,H11,0%) -> 0
A12: 4. El contrato está actualizado y firmado. La compañía de plagas cumple con lo estipulado en la normatividad. El contrato establece el alcance de servicio para cada tipo de plaga. | H12: 0.1 | I12: =IF(F12>0,H12,0%) -> 0
A13: 5. Los procedimientos consideran medidas de protección al producto, materiales y superficies, antes, durante y después de las aplicaciones. | H13: 0.1 | I13: =IF(F13>0,H13,0%) -> 0
A14: 6. El personal que realiza las actividades del programa tiene entrenamiento en: BPM´s, control de plagas, manejo seguro de químicos. Que garanticen su competencia laboral y que no serán un riesgo para la empresa. | H14: 0.1 | I14: =IF(F14>0,H14,0%) -> 0
A15: 7. La compañía de plagas realiza un reporte donde registra las actividades realizadas durante el servicio, así como registrar las cantidades de plaguicida o rodenticida utilizado durante el servicio, y realiza una recomendación hacia la planta para mejorar el control de plagas. | H15: 0.1 | I15: =IF(F15>0,H15,0%) -> 0
A16: 8. El prestador de servicio cuenta con Licencia Sanitaria. Los técnicos aplicadores cuentan con certificados de competencia laboral. | H16: 0.1 | I16: =IF(F16>0,H16,0%) -> 0
A17: 9. Constancias de tratamiento a transporte están vigente. | H17: 0.1 | I17: =IF(F17>0,H17,0%) -> 0
A18: 10. Se tiene establecido y documentado el manejo del equipo, materiales y químicos utilizados en el programa. Hay evidencia de este control. | H18: 0.1 | I18: =IF(F18>0,H18,0%) -> 0
G19: Total | H19: 1 | I19: =SUM(I9:I18) -> 0
A21: Verificación en piso | F21: Cumple | G21: No Cumple | H21: % Optimo | I21: % Obtenido | J21: Comentarios
A22: 1. Verifique en piso los dispositivos de luz, 3 trampas internas y 3 trampas externas, y verifique que corresponden a la ubicación señalada en el lay-out. | H22: 0.14 | I22: 0
A23: 2. Verifique que las áreas sensibles de la planta estén libres de plagas o evidencia de plagas. Excretas (crítico cucarachas, moscas, aves y roedores). | H23: 0.14 | I23: =IF(F23>0,H23,0%) -> 0
A24: 3. En las aplicaciones de plaguicidas se respeta la dosificación marcada en la etiqueta ya sea por mI. X litro de agua, o por metros cuadrados o cúbicos, y están registrados en el reporte de servicio. | H24: 0.14 | I24: 0
A25: 4. El proveedor de servicio de control de plagas cuenta con una capacitación sobre el manejo integrado de plaguicidas, biología y hábitos de plagas objetivo, su aplicación, y que hacer en caso de un derrame o contaminación del producto, BPM´s etc. | H25: 0.14 | I25: =IF(F25>0,H25,0%) -> 0
A26: 5. Las trampas colocadas en áreas interiores de la planta se encuentran ancladas, son suficientes para el perímetro a controlar y funcionan correctamente. | H26: 0.14 | I26: =IF(F26>0,H26,0%) -> 0
A27: 6. Se realiza seguimiento y cierre de acciones solicitadas a planta por parte del prestador de servicio. | H27: 0.14 | I27: =IF(F27>0,H27,0%) -> 0
A28: 7. Se han eliminado condiciones que puedan ocasionar contaminación del producto y proliferación de plagas, tales como: equipo en desuso, desperdicios y chatarra, maleza o hierbas, encharcamiento por drenaje insuficiente o inadecuado, grietas o claros de luz. | H28: 0.14 | I28: =IF(F28>0,H28,0%) -> 0
G29: Total | H29: 1 | I29: =SUM(I22:I28) -> 0
F31: % de cumplimiento total | I31: =AVERAGE(I19,I29) -> 0
A33: Marcar con una X el Área Evaluada
A34: 1 | B34: Almacén | G34: Fecha de verificación:
A35: 2 | B35: Aseguramiento de calidad
A36: 3 | B36: Control de calidad | G36: Nombre y Firma del Evaluador
A37: 4 | B37: Desarrollos
A38: 5 | B38: Mantenimiento | G38: Nombre y Firma del Responsables de área
A39: 6 | B39: Producción

Sheet 5.Microbiología
A4: Check list de PPR´s
A5: 5. Microbiología
A8: Verificación documental | F8: Cumple | G8: No Cumple | H8: % Optimo | I8: % Obtenido | J8: Comentarios
A9: 1. La planta cuenta con un procedimiento para el monitoreo microbiológico que tiene como alcance: monitoreo ambiental, del aire, del agua, de equipos, materias primas y producto terminado. | H9: 0.1667 | I9: =IF(F9>0,H9,0%) -> 0
A10: 2. Existe evidencia de la capacitación y competencia técnica del personal que realiza los métodos de muestreo y prueba. | H10: 0.1667 | I10: =IF(F10>0,H10,0%) -> 0
A11: 3. Si se utilizan métodos rápidos, ¿están validados contra los métodos oficiales? | H11: 0.1667 | I11: =IF(F11>0,H11,0%) -> 0
A12: 4. Las materias primas se utilizan hasta tener la liberación del resultado de microbiología. | H12: 0.1667 | I12: =IF(F12>0,H12,0%) -> 0
A13: 5. Para validar la sanidad del equipo se realizan métodos microbiológicos. | H13: 0.1667 | I13: =IF(F13>0,H13,0%) -> 0
A14: 6. Se analizan las bases de datos de los resultados microbiológicos para identificar tendencias y tomar acciones preventivas. | H14: 0.1667 | I14: =IF(F14>0,H14,0%) -> 0
G15: Total | H15: 1 | I15: =SUM(I9:I14) -> 0
A17: Verificación en piso | F17: Cumple | G17: No Cumple | H17: % Optimo | I17: % Obtenido | J17: Comentarios
A18: 1. Verifique que las frecuencias de monitoreo se cumplen como marca la matriz. (si no se cumple la frecuencia de cualquier punto de muestreo penalice el punto 2 de documentación). | H18: 0.125 | I18: 0
A19: 2. Las especificaciones tomadas para los resultados microbiológicos cumplen con las normativas nacionales, de la empresa y del cliente. | H19: 0.125 | I19: =IF(F19>0,H19,0%) -> 0
A20: 3.El personal que ingresa al área de microbiologia utiliza bata en laboratorio y es exclusiva de esa área. | H20: 0.125 | I20: 0
A21: 4. El laboratorio de microbiología cumple con las diferentes barreras para evitar una contaminación de otras áreas. | H21: 0.125 | I21: =IF(F21>0,H21,0%) -> 0
A22: 5. El acceso al laboratorio es controlado. | H22: 0.125 | I22: =IF(F22>0,H22,0%) -> 0
A23: 6. Las incubadoras cumplen con un programa formal de verificación. | H23: 0.125 | I23: =IF(F23>0,H23,0%) -> 0
A24: 7. Verifique en práctica como es desechado el material utilizado para las pruebas microbiológicas (si penaliza este punto penalice el punto 1 de documentación con la calificación mas estricta). | H24: 0.125 | I24: =IF(F24>0,H24,0%) -> 0
A25: 8.Se establecen acciones correctivas derivado de desviaciones a parámetros microbiológicos y se tiene evidencia del seguimiento? (análisis causa raíz, evidencias de cumplimiento de acciones etc.) | H25: 0.125 | I25: =IF(F25>0,H25,0%) -> 0
G26: Total | H26: 1 | I26: =SUM(I18:I25) -> 0
F28: % de cumplimiento total | I28: =AVERAGE(I15,I26) -> 0
A30: Marcar con una X el Área Evaluada
A31: 1 | B31: Almacén | G31: Fecha de verificación:
A32: 2 | B32: Aseguramiento de calidad
A33: 3 | B33: Control de calidad | G33: Nombre y Firma del Evaluador
A34: 4 | B34: Desarrollos
A35: 5 | B35: Mantenimiento | G35: Nombre y Firma del Responsables de área
A36: 6 | B36: Producción

Sheet 6.MTTO
A4: Check list de PPR´s
A5: 6. Mantenimiento
A8: Verificación documental | F8: Cumple | G8: No Cumple | H8: % Optimo | I8: % Obtenido | J8: Comentarios
A9: 1. Existe un programa documentado de mantenimiento correctivo y preventivo. Y tiene como alcance equipos, áreas de proceso e instalaciones | H9: 0.25 | I9: =IF(F9>0,H9,0%) -> 0
A10: 2. Los trabajos que son necesarios llevarlos a cabo por terceros, son supervisados para cumplir los lineamientos de este PPR; como evidencia existe un reporte de cumplimiento firmado por ambas partes. | H10: 0.25 | I10: =IF(F10>0,H10,0%) -> 0
A11: 3. Se cuenta con la evidencia de que las grasas y lubricantes utilizados en equipos son grado alimenticio (Fichas Técnicas). | H11: 0.25 | I11: =IF(F11>0,H11,0%) -> 0
A12: 4. Se han documentado los lineamientos de inocuidad para mantenimiento, por ejemplo, cómo evitar excesos de lubricación, utilización de grasas y/o lubricantes grado alimenticio, soldadura con acabado sanitario, control de químicos y herramientas, etc. | H12: 0.25 | I12: =IF(F12>0,H12,0%) -> 0
G13: Total | H13: 1 | I13: =SUM(I9:I12) -> 0
A15: Verificación en piso | F15: Cumple | G15: No Cumple | H15: % Optimo | I15: % Obtenido | J15: Comentarios
A16: 1. se realiza el inventario de herramientas y se verifica su limpieza. | H16: 0.2 | I16: 0
A17: 2. Las ordenes de mantenimiento se firman por quien realizó el mantenimiento, así como por quien recibe el servicio subcontratado. | H17: 0.2 | I17: =IF(F17>0,H17,0%) -> 0
A18: 3. Las grasas y lubricantes grado alimenticio se almacenan adecuadamente. Existe concordancia con las fichas técnicas mostradas. | H18: 0.2 | I18: 0
A19: 4. las paredes, pisos o techos se observan en buen estado | H19: 0.2 | I19: =IF(F19>0,H19,0%) -> 0
A20: 5. Existen evidencias de que los planes de mantenimiento se llevan a cabo en planta y exteriores, por ejemplo: presencia de reparaciones temporales, excesos de grasa, riesgos por material extraño, maleza crecida, goteras, etc. | H20: 0.2 | I20: =IF(F20>0,H20,0%) -> 0
G21: Total | H21: 1 | I21: =SUM(I16:I20) -> 0
F23: % de cumplimiento total | I23: =AVERAGE(I13,I21) -> 0
A25: Marcar con una X el Área Evaluada
A26: 1 | B26: Almacén | G26: Fecha de verificación:
A27: 2 | B27: Aseguramiento de calidad
A28: 3 | B28: Control de calidad | G28: Nombre y Firma del Evaluador
A29: 4 | B29: Desarrollos
A30: 5 | B30: Mantenimiento | G30: Nombre y Firma del Responsables de área
A31: 6 | B31: Producción

Sheet 7.Vidrio y plástico
A4: Check list de PPR´s
A5: 7. Control de vidrio y plástico quebradizo
A8: Verificación documental | F8: Cumple | G8: No Cumple | H8: % Optimo | I8: % Obtenido | J8: Comentarios
A9: 1. Se cuenta con inventarios por área de trabajo, se mantienen actualizados y se verifican con la frecuencia marcada por la planta. | H9: 0.25 | I9: =IF(F9>0,H9,0%) -> 0
A10: 2. Se cuenta con un procedimiento general para la entrada de objetos que contengan este material a la planta, cambio de lámparas y limpieza en caso de una contingencia. | H10: 0.25 | I10: =IF(F10>0,H10,0%) -> 0
A11: 3. Los eventos de ruptura de vidrio y/o plástico quebradizo están documentados y actualizados. | H11: 0.25 | I11: =IF(F11>0,H11,0%) -> 0
A12: 4. Los utensilios designados para la limpieza de incidencias de vidrio y/o plastico quebradizo son utilizados paa dicho fin. (el bote no deberá contener basura o algún residuo diferente). | H12: 0.25 | I12: =IF(F12>0,H12,0%) -> 0
G13: Total | H13: 1 | I13: =SUM(I9:I12) -> 0
A15: Verificación en piso | F15: Cumple | G15: No Cumple | H15: % Optimo | I15: % Obtenido | J15: Comentarios
A16: 1. Se tienen protegidas y se encuentran en buen estado las lámparas y cristales de ventanas y puertas de las áreas criticas . | H16: 0.25 | I16: 0
A17: 2. El personal respeta la política de vidrio y/o plástico quebradizo | H17: 0.25 | I17: =IF(F17>0,H17,0%) -> 0
A18: 3. Se cumple con la frecuencia de los inventarios. | H18: 0.25 | I18: 0
A19: 4. El personal asignado realiza las liberaciones de las áreas cuando ocurre un acontecimiento en las áreas de la planta. (solo aplica en producción) | H19: 0.25 | I19: =IF(F19>0,H19,0%) -> 0
G20: Total | H20: 1 | I20: =SUM(I16:I19) -> 0
F22: % de cumplimiento total | I22: =AVERAGE(I13,I20) -> 0
A24: Marcar con una X el Área Evaluada
A25: 1 | B25: Almacén | G25: Fecha de verificación:
A26: 2 | B26: Aseguramiento de calidad
A27: 3 | B27: Control de calidad | G27: Nombre y Firma del Evaluador
A28: 4 | B28: Desarrollos
A29: 5 | B29: Mantenimiento | G29: Nombre y Firma del Responsables de área
A30: 6 | B30: Producción

Sheet 8. Materia extraña
A4: Check list de PPR´s
A5: 8. Control de materia extraña
A8: Verificación documental | F8: Cumple | G8: No Cumple | H8: % Optimo | I8: % Obtenido | J8: Comentarios
A9: 1. Se tienen los registros de inspección sobre el funcionamiento de los dispositivos de control de material extraño (mallas, rejillas magnéticas). | H9: 0.25 | I9: =IF(F9>0,H9,0%) -> 0
A10: 2. Se cuenta con evidencia de verificaciones y validación de los equipos para detección de material extraño. (Malla, rejilla magnética) | H10: 0.25 | I10: =IF(F10>0,H10,0%) -> 0
A11: 3. El personal que monitoreo los prerrequisitos operativos cuenta con capacitación. | H11: 0.25 | I11: =IF(F11>0,H11,0%) -> 0
A12: 4. Se tienen bien definidas las acciones a seguir en caso de falla de las medidas de control. | H12: 0.25 | I12: =IF(F12>0,H12,0%) -> 0
G13: Total | H13: 1 | I13: =SUM(I9:I12) -> 0
A15: Verificación en piso | F15: Cumple | G15: No Cumple | H15: % Optimo | I15: % Obtenido | J15: Comentarios
A16: 1. Las áreas se mantienen libres de objetos extraños | H16: 0.3333 | I16: 0
A17: 2. Se llevan acabo las acciones correctivas marcadas en el procedimiento cuando se encuentra un material extraño (mostrar documento). | H17: 0.3333 | I17: =IF(F17>0,H17,0%) -> 0
A18: 3. La planta elimina las posibles causas de generación de material extraño en las áreas de la planta. (astillas de madera, plástico o letreros rotos etc.) | H18: 0.3333 | I18: 0
G19: Total | H19: 1 | I19: =SUM(I16:I18) -> 0
F21: % de cumplimiento total | I21: =AVERAGE(I13,I19) -> 0
A23: Marcar con una X el Área Evaluada
A24: 1 | B24: Almacén | G24: Fecha de verificación:
A25: 2 | B25: Aseguramiento de calidad
A26: 3 | B26: Control de calidad | G26: Nombre y Firma del Evaluador
A27: 4 | B27: Desarrollos
A28: 5 | B28: Mantenimiento | G28: Nombre y Firma del Responsables de área
A29: 6 | B29: Producción

Sheet 9.Alérgenos
A4: Check list de PPR´s
A5: 9. Control de alérgenos.
A8: Verificación documental | F8: Cumple | G8: No Cumple | H8: % Optimo | I8: % Obtenido | J8: Comentarios
A9: 1. Se cuenta con una lista actualizada de los alérgenos que hay en planta y el personal los ubica. | H9: 0.14 | I9: =IF(F9>0,H9,0%) -> 0
A10: 2.-Se cuenta con las fichas técnicas de los productos alérgenos o sustancias sensitivas | H10: 0.14 | I10: =IF(F10>0,H10,0%) -> 0
A11: 3.-Se cuenta con un procedimiento para el manejo de alérgenos que abarque su almacenamiento e indique qué hacer cuando ocurre un derrame, así como para evitar las posibles contaminaciones del material a los trabajadores. También las posibles contaminaciones cruzadas por mal manejo de utensilios y disposición de materiales. | H11: 0.14 | I11: =IF(F11>0,H11,0%) -> 0
A12: 4. Se han establecido criterios para la recepción de materias identificadas como alérgenos. | H12: 0.14 | I12: =IF(F12>0,H12,0%) -> 0
A13: 5. Se encuentran registros que demuestren que el personal es capacitado en el programa de alérgenos y materiales sensitivos. | H13: 0.14 | I13: =IF(F13>0,H13,0%) -> 0
A14: 6. El listado de alérgenos aparece en el análisis de riesgos de ingredientes en el plan HACCP. | H14: 0.14 | I14: =IF(F14>0,H14,0%) -> 0
A15: 7.-Se cuenta con un procedimiento para realizar las limpiezas de las líneas donde se procesaron alérgenos y su liberación. | H15: 0.14 | I15: =IF(F15>0,H15,0%) -> 0
G16: Total | H16: 1 | I16: =SUM(I9:I15) -> 0
A18: Verificación en piso | F18: Cumple | G18: No Cumple | H18: % Optimo | I18: % Obtenido | J18: Comentarios
A19: 1. Los alérgenos están identificados y se almacenan adecuadamente, separados de los ingredientes no alérgenos. | H19: 0.14 | I19: 0
A20: 2. El personal de la planta conoce el manejo de alérgenos y cómo actuar ante una contingencia relacionado con los mismos. | H20: 0.14 | I20: 0
A21: 3. Se utilizan programas de producción y métodos de limpieza para prevenir la contaminación cruzada. | H21: 0.14 | I21: 0
A22: 4. Se cuenta con utensilios especiales para el manejo de alérgenos. | H22: 0.14 | I22: 0
A23: 5. En áreas donde los sacos o contenedores de alérgenos son abiertos para ser pesados o dosificados, se cumplen los lineamientos del programa para evitar la contaminación cruzada. | H23: 0.14 | I23: 0
A24: 6.Los alérgenos del comedor son manejados adecuadamente para evitar contaminación cruzada y se tiene identificado al personal que es alérgico. | H24: 0.14 | I24: =IF(F24>0,H24,0%) -> 0
A25: 7.Se cumple la restricción de no ingresar con bata al comedor para evitar contaminación cruzada. | H25: 0.14 | I25: 0
G26: Total | H26: 1 | I26: =SUM(I19:I25) -> 0
F28: % de cumplimiento total | I28: =AVERAGE(I16,I26) -> 0
A30: Marcar con una X el Área Evaluada
A31: 1 | B31: Almacén | G31: Fecha de verificación:
A32: 2 | B32: Aseguramiento de calidad
A33: 3 | B33: Control de calidad | G33: Nombre y Firma del Evaluador
A34: 4 | B34: Desarrollos
A35: 5 | B35: Mantenimiento | G35: Nombre y Firma del Responsables de área
A36: 6 | B36: Producción

Sheet 10. Recuperación y trazabilidad
A4: Check list de PPR´s
A5: 10. Recuperación y Trazabilidad
A8: Verificación documental | F8: Cumple | G8: No Cumple | H8: % Optimo | I8: % Obtenido | J8: Comentarios
A9: 1. Se cuenta con el procedimiento para realizar la trazabilidad del producto terminado y/o materias primas | H9: 0.25 | I9: =IF(F9>0,H9,0%) -> 0
A10: 2. La duración de los ejercicios de trazabilidad deberá de estar marcada en el procedimiento (2 horas) y una frecuencia de dos veces por año. | H10: 0.25 | I10: =IF(F10>0,H10,0%) -> 0
A11: 3. Se cuenta con un procedimiento de recuperación y está documentado para casos reales como simulados y se lleva a cabo. | H11: 0.25 | I11: =IF(F11>0,H11,0%) -> 0
A12: 4. El personal involucrado está capacitado de acuerdo al procedimiento establecido. | H12: 0.25 | I12: =IF(F12>0,H12,0%) -> 0
G13: Total | H13: 1 | I13: =SUM(I9:I12) -> 0
A15: Verificación en piso | F15: Cumple | G15: No Cumple | H15: % Optimo | I15: % Obtenido | J15: Comentarios
A16: 1. Verifique que a lo largo del proceso, desde recepción hasta distribución, tanto ingredientes, producto en proceso y terminado tenga una forma de identificarse (código / lote) y que permita seguir su trazabilidad. | H16: 0.3333 | I16: 0
A17: 2. Se tiene registro de la realización de simulacros de rastreo y recuperación de producto | H17: 0.3333 | I17: 0
A18: 3. Se han tomado acciones preventivas para atender los hallazgos durante el ejercicio de trazabilidad y /o recuperación de producto. | H18: 0.3333 | I18: 0
G19: Total | H19: 1 | I19: =SUM(I16:I18) -> 0
F21: % de cumplimiento total | I21: =AVERAGE(I13,I19) -> 0
A23: Marcar con una X el Área Evaluada
A24: 1 | B24: Almacén | G24: Fecha de verificación:
A25: 2 | B25: Aseguramiento de calidad
A26: 3 | B26: Control de calidad | G26: Nombre y Firma del Evaluador
A27: 4 | B27: Desarrollos
A28: 5 | B28: Mantenimiento | G28: Nombre y Firma del Responsables de área
A29: 6 | B29: Producción

Sheet 11.Calibración
A4: Check list de PPR´s
A5: 11. Calibración
A8: Verificación documental | F8: Cumple | G8: No Cumple | H8: % Optimo | I8: % Obtenido | J8: Comentarios
A9: 1. Se cuenta con un programa de calibración e involucra todos los equipos susceptibles de realizar una medición y que intervenga en la fabricación, pudiendo afectar la calidad e inocuidad del producto. | H9: 0.1667 | I9: =IF(F9>0,H9,0%) -> 0
A10: 2. Los responsables de área donde se tienen equipos de medición de nueva adquisición consideran la calibración previa a su uso. | H10: 0.1667 | I10: =IF(F10>0,H10,0%) -> 0
A11: 3. Se cuenta con el respaldo de que los laboratorios donde se mandan los equipos a calibrar son laboratorios acreditados por entes legales. | H11: 0.1667
A12: 4. El procedimiento define un código para cada equipo y así poder tener una trazabilidad documental y física. | H12: 0.1667
A13: 5.Los equipos de medición utilizados en las diferentes áreas son los autorizados. | H13: 0.1667 | I13: =IF(F13>0,H13,0%) -> 0
A14: 6. Se cuenta con los registros de certificación de los patrones utilizados en planta. | H14: 0.1667 | I14: =IF(F14>0,H14,0%) -> 0
G15: Total | H15: 1 | I15: =SUM(I9:I14) -> 0
A17: Verificación en piso | F17: Cumple | G17: No Cumple | H17: % Optimo | I17: % Obtenido | J17: Comentarios
A18: 1. Los equipos mencionados en el programa de calibración deben contar con una identificación así su como evidencia de su calibración. | H18: 0.25 | I18: 0
A19: 2. Se reciben certificados de las calibraciones realizadas por externos. | H19: 0.25 | I19: 0
A20: 3. El personal sabe que hacer en caso de identificar un equipo que no funcione correctamente | H20: 0.25
A21: 4.Los responsables de área que tienen equipos de medición y actualizan el programa de calibración. | H21: 0.25 | I21: 0
G22: Total | H22: 1 | I22: =SUM(I18:I21) -> 0
F24: % de cumplimiento total | I24: =AVERAGE(I15,I22) -> 0
A26: Marcar con una X el Área Evaluada
A27: 1 | B27: Almacén | G27: Fecha de verificación:
A28: 2 | B28: Aseguramiento de calidad
A29: 3 | B29: Control de calidad | G29: Nombre y Firma del Evaluador
A30: 4 | B30: Desarrollos
A31: 5 | B31: Mantenimiento | G31: Nombre y Firma del Responsables de área
A32: 6 | B32: Producción

Sheet 12. Almacenamiento.
A4: Check list de PPR´s
A5: 12. Almacenamiento
A8: Verificación documental | F8: Cumple | G8: No Cumple | H8: % Optimo | I8: % Obtenido | J8: Comentarios
A9: 1. Se tienen procedimientos de recepción, almacenamiento y Despacho de producto terminado y son son conocidos por el personal que realiza la carga y la descarga de materiales y de producto terminado. | H9: 0.2 | I9: =IF(F9>0,H9,0%) -> 0
A10: 2. Se tienen todas las especificaciones de los materiales e ingredientes utilizados para la fabricación de los alimentos. | H10: 0.2 | I10: =IF(F10>0,H10,0%) -> 0
A11: 3. Se cuenta con un sistema que asegure que tanto los ingredientes, insumos y producto terminado se despachen de acuerdo a sus fechas de ingreso o fechas de caducidad. | H11: 0.2 | I11: =IF(F11>0,H11,0%) -> 0
A12: 4. Se cuenta con un sistema para identificar primeras entradas - primeras salidas. | H12: 0.2 | I12: =IF(F12>0,H12,0%) -> 0
A13: 5. Se cuenta con un sistema para bloquear el producto no conforme y este no sea distribuido a cliente. | H13: 0.2 | I13: =IF(F13>0,H13,0%) -> 0
G14: Total | H14: 1 | I14: =SUM(I9:I13) -> 0
A16: Verificación en piso | F16: Cumple | G16: No Cumple | H16: % Optimo | I16: % Obtenido | J16: Comentarios
A17: 1. Se tienen certificados de calidad de los materiales recibidos, y se expide un certificado cuando se despacha producto terminado. | H17: 0.111 | I17: 0
A18: 2. Se realizan las revisiones de los transportes antes de cargar y descargar, en base a un check list (ver evidencia). Se realizan observaciones a los operadores de los camiones sobre las mejoras se tienen que hacer a su unidad. | H18: 0.111 | I18: 0
A19: 3. El producto terminado se almacena de una manera que se prevenga la contaminación del producto. | H19: 0.111 | I19: 0
A20: 4. La franja sanitaria y/o espacios detrás de los racks se observa limpia, libre de evidencia de plaga o materia extraña | H20: 0.111 | I20: 0
A21: 5. Se tienen identificadas todas las materias primas, excepto aquellas cuya identificación sea evidente. | H21: 0.111 | I21: 0
A22: 6. Se encuentran identificados los materiales almacenados con status de calidad (liberado, rechazado o en cuarentena). | H22: 0.111 | I22: =IF(F22>0,H22,0%) -> 0
A23: 7. Se tiene asignado un área para producto no conforme | H23: 0.111 | I23: 0
A24: 8. Todos los materiales e ingredientes se almacenan por separado de producto terminado, asegurando condiciones que eviten su contaminación. | H24: 0.111 | I24: 0
A25: 9. Los contenedores que son abiertos para su muestreo son debidamente cerrados e identificados. | H25: 0.111 | I25: 0
G26: Total | H26: 1 | I26: =SUM(I17:I25) -> 0
F28: % de cumplimiento total | I28: =AVERAGE(I14,I26) -> 0
A30: Marcar con una X el Área Evaluada
A31: 1 | B31: Almacén | G31: Fecha de verificación:
A32: 2 | B32: Aseguramiento de calidad
A33: 3 | B33: Control de calidad | G33: Nombre y Firma del Evaluador
A34: 4 | B34: Desarrollos
A35: 5 | B35: Mantenimiento | G35: Nombre y Firma del Responsables de área
A36: 6 | B36: Producción

Sheet 13. Compras
A4: Check list de PPR´s
A5: 13. Compras
A8: Verificación documental | F8: Cumple | G8: No Cumple | H8: % Optimo | I8: % Obtenido | J8: Comentarios
A9: 1. Se cuenta con un procedimiento para la selección y evaluación de proveedores. | H9: 0.2 | I9: =IF(F9>0,H9,0%) -> 0
A10: 2. Se tienen el listado de proveedores autorizados. | H10: 0.2 | I10: =IF(F10>0,H10,0%) -> 0
A11: 3. Se tiene evidencia de evaluación a proveedores de ingredientes, empaques y de servicio. Cuestionarios, check list, base de datos. | H11: 0.2 | I11: =IF(F11>0,H11,0%) -> 0
A12: 4. Se define en el procedimiento el lapso de tiempo que tienen los proveedores para establecer acciones correctivas sobre los hallazgos. | H12: 0.2 | I12: =IF(F12>0,H12,0%) -> 0
A13: 5. Se verifica el cumplimiento normativo que deben cumplir los proveedores de ingredientes y servicio. | H13: 0.2 | I13: =IF(F13>0,H13,0%) -> 0
G14: Total | H14: 1 | I14: =SUM(I9:I13) -> 0
A16: Verificación en piso | F16: Cumple | G16: No Cumple | H16: % Optimo | I16: % Obtenido | J16: Comentarios
A17: 1.- Verifique algunas materias primas y corrobore que los proveedores de las mismas son proveedores autorizados. | H17: 0.3333 | I17: 0
A18: 2.- Se cuenta con cartas de garantía y certificados de calidad de los proveedores de materias primas y material de empaque primario. Verifique 3 que se hayan recibido recientemente. | H18: 0.3333 | I18: 0
A19: 4.- Revise en piso si el personal de almacén conoce y está consciente de la documentación que debe entregar proveedores de materias primas y material de empaque para aceptar un embarque. | H19: 0.3333 | I19: 0
G20: Total | H20: 1 | I20: =SUM(I17:I19) -> 0
F22: % de cumplimiento total | I22: =AVERAGE(I14,I20) -> 0
A24: Marcar con una X el Área Evaluada
A25: 1 | B25: Almacén | G25: Fecha de verificación:
A26: 2 | B26: Aseguramiento de calidad
A27: 3 | B27: Control de calidad | G27: Nombre y Firma del Evaluador
A28: 4 | B28: Desarrollos
A29: 5 | B29: Mantenimiento | G29: Nombre y Firma del Responsables de área
A30: 6 | B30: Producción

Sheet 14. Defensa
A4: Check list de PPR´s
A5: 14. Defensa de Alimentos
A8: Verificación documental | F8: Cumple | G8: No Cumple | H8: % Optimo | I8: % Obtenido | J8: Comentarios
A9: 1. Se tiene un plan de defensa de alimentos que contempla acceso controlado, seguridad de la información, monitoreo de cámaras de seguridad etc. | H9: 0.2 | I9: =IF(F9>0,H9,0%) -> 0
A10: 2. Se cuenta con un análisis de vulnerabilidad de las instalaciones y operaciones sensibles. | H10: 0.2 | I10: =IF(F10>0,H10,0%) -> 0
A11: 3. El personal cuenta con capacitación sobre defensa de alimentos. | H11: 0.2 | I11: =IF(F11>0,H11,0%) -> 0
A12: 4. Se cuenta con evidencia del seguimiento a las vulnerabilidadel detectadas. | H12: 0.2 | I12: =IF(F12>0,H12,0%) -> 0
A13: 5. La contratación de personal nuevo es apoyada por herramientas de evaluación de confianza (psicométricos, estudios socioeconómicos, referencias, etc.) | H13: 0.2 | I13: =IF(F13>0,H13,0%) -> 0
G14: Total | H14: 1 | I14: =SUM(I9:I13) -> 0
A16: Verificación en piso | F16: Cumple | G16: No Cumple | H16: % Optimo | I16: % Obtenido | J16: Comentarios
A17: 1. El programa de control de acceso al personal es llevado adecuadamente. | H17: 0.2 | I17: 0
A18: 2. El sistema de CCV funciona correctamente y es monitoreado continuamente. | H18: 0.2 | I18: 0
A19: 3. El acceso a las instalaciones se encuentra restringido a personal no autorizado a través de candados, letreros, puertas con clave, etc. | H19: 0.2 | I19: 0
A20: 4. El personal identifica los controles establecidos para el programa de defensa de alimentos.Mencione ejemplos | H20: 0.2 | I20: 0
A21: 5. Los visitantes portan identificación y su desplazamiento o actividad dentro de la instalación es supervisada por personal de la planta. | H21: 0.2 | I21: 0
G22: Total | H22: 1 | I22: =SUM(I17:I21) -> 0
F24: % de cumplimiento total | I24: =AVERAGE(I14,I22) -> 0
A26: Marcar con una X el Área Evaluada
A27: 1 | B27: Almacén | G27: Fecha de verificación:
A28: 2 | B28: Aseguramiento de calidad
A29: 3 | B29: Control de calidad | G29: Nombre y Firma del Evaluador
A30: 4 | B30: Desarrollos
A31: 5 | B31: Mantenimiento | G31: Nombre y Firma del Responsables de área
A32: 6 | B32: Producción

Sheet 15. Residuos
A4: Check list de PPR´s
A5: 15. Gestión de residuos
A8: Verificación documental | F8: Cumple | G8: No Cumple | H8: % Optimo | I8: % Obtenido | J8: Comentarios
A9: 1.Se tiene un procedimiento para gestión de desechos. | H9: 0.3333 | I9: =IF(F9>0,H9,0%) -> 0
A10: 2.Se tiene un proveedor autorizado por SEMARNAT para retiro y traslado de residuos peligrosos y los permisos están vigentes. | H10: 0.3333 | I10: =IF(F10>0,H10,0%) -> 0
A11: 3.Se tiene capacitación del personal en la gestión de desechos y residuos de manejo especial. | H11: 0.3333 | I11: =IF(F11>0,H11,0%) -> 0
G12: Total | H12: 1 | I12: =SUM(I9:I11) -> 0
A14: Verificación en piso | F14: Cumple | G14: No Cumple | H14: % Optimo | I14: % Obtenido | J14: Comentarios
A15: 1. Los contenedores de desechos se encuentran identificados y con tapa. Además de que no están desbordados de desechos, están limpios y en buenas condiciones físicas. | H15: 0.1429 | I15: 0
A16: 2.Los desechos se colocan en el contenedor respectivo. | H16: 0.1429 | I16: 0
A17: 3.Se observa que se retiran los desechos frecuentemente del interior de la instalación. | H17: 0.1429 | I17: 0
A18: 4.Las áreas de almacenamiento de desechos se encuentran identificadas, delimitadas y en orden. | H18: 0.1429 | I18: 0
A19: 5.Los residuos peligrosos se depositan en sus contenedores respectivos y se cuenta con los manifiestos correspondientes una vez que son retirados de planta | H19: 0.1429 | I19: 0
A20: 6.Se cuenta con evidencia del retiro de residuos sólidos urbanos de la instalción. | H20: 0.1429 | I20: 0
A21: 7.El personal identifica que tipo de desechos se genera en su área ( residuo especial o residuos peligrosos). Que mencione al menos 1 ejemplo | H21: 0.1429 | I21: 0
G22: Total | H22: 1 | I22: =SUM(I15:I21) -> 0
F24: % de cumplimiento total | I24: =AVERAGE(I12,I22) -> 0
A26: Marcar con una X el Área Evaluada
A27: 1 | B27: Almacén | G27: Fecha de verificación:
A28: 2 | B28: Aseguramiento de calidad
A29: 3 | B29: Control de calidad | G29: Nombre y Firma del Evaluador
A30: 4 | B30: Desarrollos
A31: 5 | B31: Mantenimiento | G31: Nombre y Firma del Responsables de área
A32: 6 | B32: Producción

Sheet HACCP
B2: PLANTA
B3: GERENCIA GENERAL
B4: HACCP
A6: Verificación de documentación | E6: Cumple | F6: No Cumple | G6: % Optimo | H6: % Obtenido | I6: % Seguimiento | J6: Observaciones
A7: 1. Se tiene un análisis de materia prima. Revise dos que estén de acuerdo a lo documentado. | G7: 0.04
A8: 2. Los diagramas de flujo de proceso están actualizados. | G8: 0.04
A9: 3. Los planes maestros se encuentran en las líneas donde están los PCCs. | G9: 0.04
A10: 4. Los datos de los miembros del equipo HACCP se encuentran documentados y actualizados. | G10: 0.04
A11: 5. El equipo HACCP se reúne con una frecuencia adecuada para la revisión y mantenimiento del programa | G11: 0.04
A12: 6. Los Planes HACCP concuerdan con las definiciones y directrices del CODEX y NOM 251 para la aplicación de los siete principios del HACCP. | G12: 0.04
A13: 7. Los planes HACCP incluyen: descripción del producto, incluyendo distribución, uso destinado, y consumidores a los que se dirige. | G13: 0.04
A14: 8. Describa las auditorias / revisiones del Sistema HACCP realizadas para determinar si está operando de acuerdo con el Plan HACCP. | G14: 0.04
A15: 9.-Se cuenta con un análisis de peligros por proceso. | G15: 0.04
A16: 10. El personal que monitorea el PCC ha sido capacitado, tiene conciencia de su función, la toma con la responsabilidad adecuada y domina la actividad. | G16: 0.04
F17: Total | G17: 0.4
E19: Cumple | F19: No Cumple | G19: % Optimo | H19: % Obtenido | I19: % Seguimiento | J19: Observaciones
A20: 1. Los PCCs están identificados físicamente. | G20: 0.06
A21: 2. Se sigue la frecuencia de monitoreo ( si se penaliza este punto penalice el punto 5 de documentación). | G21: 0.06
A22: 3. Los límites críticos se respetan y los registros son claros. Cuentan con la firma del monitor ( si se penaliza este punto penalice el punto 5 de documentación). | G22: 0.06
A23: 4. Se han documentado los PR´s operativos. | G23: 0.06
A24: 5. Describa los procedimientos de validación de los límites críticos (cite el estudio interno, número/ fecha, referencia científica, etc.) | G24: 0.06
A25: 6. Se cuenta con los procedimientos de re-evaluación del Plan HACCP; e.g. anual, o en respuesta a algún cambio o nueva información que pudiera afectar la validez del Plan HACCP. Verifique la fecha de la última re-evaluación. | G25: 0.06
A26: 7. Los registros HACCP son fácilmente accesibles. | G26: 0.06
A27: 8. Se llevan a cabo las verificaciones en tiempo, y a su vez documentados (si se penaliza este punto penalice el punto 3 de documentación). | G27: 0.06
A28: 9. Existe un resguardo de los documentos del sistema HACCP, y a su vez la documentación se encuentra actualizada. | G28: 0.06
A29: 10. Las acciones correctivas se documentan cuando se exceden los límites críticos. El personal conoce los procedimientos para desviaciones y manejo de producto bajo sospecha de contaminación. | G29: 0.06
F30: Total | G30: 0.6
F32: Cumplimiento Total | H32: =H30+H17 -> 0
F34: Seguimiento
A35: Fecha:
A37: Nombre, puesto y firma evaluador:
A39: Nombre, puesto y firma evaluado:
