Workbook
Name Acciones: #REF!
Name Acciones: #REF!
Name Acciones: #REF!
Name Acciones: #REF!
Name asi: #REF!
Name CENT1: #REF!
Name CENT1: #REF!
Name CENT1: #REF!
Name CENT1: #REF!
Name DECE1: #REF!
Name DECE1: #REF!
Name DECE1: #REF!
Name DECE1: #REF!
Name DECE2: #REF!
Name doce: #REF!
Name Est: #REF!
Name Est: #REF!
Name Est: #REF!
Name Est: #REF!
Name FACTURA: #REF!
Name FACTURAS: #REF!
Name FACTURAS: #REF!
Name FACTURAS: #REF!
Name FACTURAS: #REF!
Name iniciar: #REF!
Name Iniciativa: #REF!
Name Iniciativa: #REF!
Name Iniciativa: #REF!
Name Iniciativa: #REF!
Name Iniciativas: #REF!
Name Iniciativas: #REF!
Name Iniciativas: #REF!
Name Iniciativas: #REF!
Name insight: #REF!
Name PA: #REF!
Name planesyacciones: #REF!
Name QUIN1: #REF!
Name QUIN1: #REF!
Name QUIN1: #REF!
Name QUIN1: #REF!
Name QUIN2: #REF!
Name UNID1: #REF!
Name UNID1: #REF!
Name UNID1: #REF!
Name UNID1: #REF!
Name UNID3: #REF!
Name VALOR: #REF!
Name VALOR1: #REF!
Name VALOR1: #REF!
Name VALOR1: #REF!
Name VALOR1: #REF!
Name VALOR2: #REF!

Sheet Objetivos
A5: Análisis FODA
A7: OBJETIVOS DEL SGI
A9: Objetivo 1 | B9: ¿Qué? | E9: Meta | F9: Estrategia ¿Cómo? | G9: Medida
A16: Objetivo 2 | B16: ¿Qué? | E16: Meta | F16: Estrategia ¿Cómo?
A21: Objetivo 3 | B21: ¿Qué? | E21: Meta | F21: Estrategia ¿Cómo?
A28: Fecha de último análisis:
A29: Participantes:

Sheet Análisis
B4: Analisis FODA
B6: Objetivo 1 | C6: =+Objetivos!A11 -> 0
B8: Fortalezas | C8: Debilidades | D8: Oportunidades | E8: Amenazas
B9: F1 | C9: D1 | D9: O1 | E9: A1
B10: F2 | C10: D2 | D10: O2 | E10: A2
B11: F3 | C11: D3 | D11: O3 | E11: A3
B12: F4 | C12: D4 | D12: O4 | E12: A4
B13: F5 | C13: D5 | D13: O5 | E13: A5
B14: F6 | C14: D6 | D14: O6 | E14: A6
B15: F7 | C15: D7 | D15: O7 | E15: A7
B16: F8 | C16: D8 | D16: O8 | E16: A8
B17: F9 | C17: D9 | D17: O9 | E17: A9
B18: F10 | C18: D10 | D18: O10 | E18: A10
B20: Objetivo 2 | C20: =+Objetivos!A18 -> 0
B22: Fortalezas | C22: Debilidades | D22: Oportunidades | E22: Amenazas
B23: F1 | C23: D1 | D23: O1 | E23: A1
B24: F2 | C24: D2 | D24: O2 | E24: A2
B25: F3 | C25: D3 | D25: O3 | E25: A3
B26: F4 | C26: D4 | D26: O4 | E26: A4
B27: F5 | C27: D5 | D27: O5 | E27: A5
B28: F6 | C28: D6 | D28: O6 | E28: A6
B30: Objetivo 3 | C30: =+Objetivos!A23 -> 0
B32: Fortalezas | C32: Debilidades | D32: Oportunidades | E32: Amenazas
B33: F1 | C33: D1 | D33: O1 | E33: A1
B34: F2 | C34: D2 | D34: O2 | E34: A2
B35: F3 | C35: D3 | D35: O3 | E35: A3
B37: Objetivo 4 | C37: =+Objetivos!#REF! -> #REF!
B39: Fortalezas | C39: Debilidades | D39: Oportunidades | E39: Amenazas
B40: F1 | C40: D1 | D40: O1 | E40: A1
B41: F2 | C41: D2 | D41: O2 | E41: A2
B42: F3 | C42: D3 | D42: O3 | E42: A3
B43: F4 | C43: D4 | D43: O4 | E43: A4
B44: F5 | C44: D5 | D44: O5 | E44: A5
B45: F6 | C45: D6 | D45: O6 | E45: A6
B46: F7 | C46: D7 | D46: O7 | E46: A7
B47: F8 | C47: D8 | D47: O8 | E47: A8
B48: F9 | C48: D9 | D48: O9 | E48: A9
B49: F10 | C49: D10 | D49: O10 | E49: A10

Sheet FODA
A4: Analisis FODA
A6: Análisis situacional Integral
D8: EXTERNO
D9: Oportunidades | E9: Total | F9: Amenazas | G9: total
A10: CRITERIOS | D10: =+Análisis!D9 -> O1 | E10: 3 | F10: =+Análisis!E9 -> A1 | G10: 1
A11: 3. Alto impacto | D11: =+Análisis!D10 -> O2 | E11: 3 | F11: =+Análisis!E10 -> A2 | G11: 3
A12: 2. Medio | D12: =+Análisis!D23 -> O1 | E12: 2 | F12: =+Análisis!E11 -> A3 | G12: 3
A13: 1. Bajo impacto | D13: =+Análisis!D24 -> O2 | E13: 2 | F13: =+Análisis!E12 -> A4 | G13: 1
D14: =+Análisis!D33 -> O1 | E14: 1 | F14: =+Análisis!E13 -> A5 | G14: 1
D15: =+Análisis!D14 -> O6 | F15: =+Análisis!E14 -> A6 | G15: 2
D16: =+Análisis!D15 -> O7 | F16: =+Análisis!E15 -> A7 | G16: 3
D17: =+Análisis!D16 -> O8 | F17: =+Análisis!E16 -> A8 | G17: 1
D18: =+Análisis!D18 -> O10 | F18: =+Análisis!E17 -> A9 | G18: 3
F19: =+Análisis!E18 -> A10 | G19: 3
F20: =+Análisis!E23 -> A1 | G20: 2
F21: =+Análisis!E24 -> A2 | G21: 1
F22: =+Análisis!E33 -> A1 | G22: 2
F23: =+Análisis!E34 -> A2 | G23: 2
D24: PROMEDIO | E24: =AVERAGE(E10:E15) -> 2.2 | F24: PROMEDIO | G24: =AVERAGE(G10:G23) -> 2
A25: INTERNO | D25: =SUM(E10:E22) -> 11 | F25: =SUM(G10:G22) -> 26
A26: Fortalezas | B26: total | C26: =SUM(B27:B40) -> 39 | D26: =D25+C26 -> 50 | F26: =F25+C26 -> 65
A27: =+Análisis!B9 -> F1 | B27: 3
A28: =+Análisis!B10 -> F2 | B28: 3
A29: =+Análisis!B11 -> F3 | B29: 3
A30: =+Análisis!B12 -> F4 | B30: 3
A31: =+Análisis!B13 -> F5 | B31: 3
A32: =+Análisis!B14 -> F6 | B32: 3
A33: =+Análisis!B23 -> F1 | B33: 3
A34: =+Análisis!B24 -> F2 | B34: 3
A35: =+Análisis!B25 -> F3 | B35: 3
A36: =+Análisis!B26 -> F4 | B36: 3
A37: =+Análisis!B33 -> F1 | B37: 3
A38: =+Análisis!B34 -> F2 | B38: 3
A39: =+Análisis!B35 -> F3 | B39: 3
A40: =+Análisis!B27 -> F5 | D40: =D26/(D26+F26+D42+F42) -> 0.24271845 | F40: =F26/(F26+D26+D42+F42) -> 0.31553398
A41: PROMEDIO | B41: =AVERAGE(B27:B40) -> 3
A42: Debilidades | B42: total | C42: =SUM(B43:B56) -> 27 | D42: =C42+D25 -> 38 | F42: =F25+C42 -> 53
A43: =+Análisis!C9 -> D1 | B43: 2
A44: =+Análisis!C10 -> D2 | B44: 2
A45: =+Análisis!C11 -> D3 | B45: 3
...
